Workbook

Sheet 🏠 INICIO
B1: AMYSA · GESTIÓN DE VENTAS POR CATÁLOGO | F1: #VALUE!
B4: Yanbal • Esika • Cyzone • LBel • Natura • Avon • Farmasi • Oriflame
B6: ⚙️ CONFIGURA TU SISTEMA AQUÍ (solo toca estas 3 celdas)
B7: 👤 Tu nombre de consultora: | C7: MARIABEL | D7: ← escribe tu nombre aquí
B8: 💰 Tu % de comisión base: | C8: 0.1 | D8: Precio de comision que las vendedoras (en caso la tengas o tu misma si eres la que vende tambien) reciben
B9: 📅 Año de control: | C9: 2025 | D9: ← el año que estás registrando
G10: 25
B11: 📋 GUÍA DE HOJAS — ¿QUÉ HACE CADA UNA? | G11: 0.1
B12: 💰 PRECIOS BASE | C12: Tu menú permanente de productos: qué te cuesta, cuánto venderlo y tu margen. | G12: =G10*G11 -> 2.5
C13: 📌 CONFIGURA UNA VEZ. Solo cuando agregas un producto nuevo o cambia su precio.
B15: 📊 CALCULADORA CAMPAÑA | C15: Registra los productos vendidos en UNA campaña y calcula ganancia + comisión.
C16: ✅ ÚSALA CADA CAMPAÑA. Una campaña = una vez cada ~3 semanas.
B18: 💵 ¿CUÁNTO ME PAGO? | C18: Tu sueldo real: cuánto separar para pagarte, cubrir costos y reinvertir.
C19: 🎯 REVÍSALA CADA CAMPAÑA. Aquí sabes si tu negocio es rentable.
B21: 🗂️ MONITOREO CATÁLOGOS | C21: Resumen por catálogo: factura, ventas reales y ganancia neta por marca.
C22: 📈 ÚSALA CADA MES. Ingresa factura y ventas reales de cada catálogo.
B24: 📅 SEG - ENERO … DIC | C24: Registro detallado de cada venta: cliente, producto, pago y estado.
C25: 📝 ÚSALA DIARIO. Anota cada venta en el mes que corresponde.
B27: 📊 RESUMEN ANUAL | C27: Dashboard de todo el año: ventas, comisiones y gráficos mes a mes.
C28: 👀 SOLO LECTURA. Se calcula solo con los datos que vayas ingresando.
B30: 🧾 FACTURAS | C30: Control de facturas por catálogo: lo que debes pagar a cada empresa.
C31: 💳 ÚSALA AL CERRAR CAMPAÑA. Registra cuánto debes pagar a cada catálogo.
B34: 🎨 LEYENDA DE COLORES EN LAS TABLAS
B35: 🔵 CELDA AZUL sobre fondo amarillo | C35: Aquí TÚ ingresas datos (precio, nombre, cantidad, etc.)
B36: ⚫ CELDA AZUL sobre fondo azul claro | C36: Calculado automáticamente — NO lo edites
B37: 🟢 CELDA VERDE | C37: Tu ganancia o dinero que entra
B38: 🔴 CELDA ROJA | C38: Costo, gasto o dinero que sale

Sheet COSTO UNITARIO
B2: 🧮 CALCULADORA DE COSTO UNITARIO — ¿Cuánto me cuesta cada producto que vendo?
B3: Llena solo las celdas AMARILLAS 🟡 — las azules se calculan solas automáticamente ⚡
B5: 📦 PASO 1 — Costos Variables (lo que compras por lote) | G5: 🏢 PASO 2 — Costos Fijos (gastos del negocio cada mes)
B6: Material / Insumo | C6: Precio del lote (S/) | D6: Cantidad en el lote | E6: Costo por unidad (S/) | G6: Gasto Mensual | H6: Costo S/ | J6: Costo por pedido (S/)
B7: Bolsas | C7: 180 | D7: 1000 | E7: =IF(AND(C7<>"",D7<>"",D7<>0),C7/D7,"") -> 0.18 | G7: Luz | H7: 25 | J7: =H7 -> 25
B8: Caja provincia | C8: 120 | D8: 100 | E8: =IF(AND(C8<>"",D8<>"",D8<>0),C8/D8,"") -> 1.2 | G8: Internet | H8: 25 | J8: =H8 -> 25
B9: Cinta adhesiva | C9: 5 | D9: 50 | E9: =IF(AND(C9<>"",D9<>"",D9<>0),C9/D9,"") -> 0.1 | G9: Publicidad / redes | H9: 100 | J9: =H9 -> 100
B10: Film stretch | C10: 18 | D10: 100 | E10: =IF(AND(C10<>"",D10<>"",D10<>0),C10/D10,"") -> 0.18 | G10: Celular (depreciación) | H10: 52.78 | J10: =H10 -> 52.78
B11: Tarjetas agradecimiento | C11: 35 | D11: 1000 | E11: =IF(AND(C11<>"",D11<>"",D11<>0),C11/D11,"") -> 0.035 | G11: Marketing | H11: 100 | J11: =H11 -> 100
B12: Papel de seda | C12: 2 | D12: 12 | E12: =IF(AND(C12<>"",D12<>"",D12<>0),C12/D12,"") -> 0.16666667 | G12: Sueldo de gerente | H12: 200 | J12: =H12 -> 200
E13: =IF(AND(C13<>"",D13<>"",D13<>0),C13/D13,"") | G13: Sueldo logística | H13: 50 | J13: =H13 -> 50
E14: =IF(AND(C14<>"",D14<>"",D14<>0),C14/D14,"") | G14: Contador | H14: 30 | J14: =H14 -> 30
E15: =IF(AND(C15<>"",D15<>"",D15<>0),C15/D15,"") | G15: Tijera | H15: 2 | I15: 200 | J15: =IF(AND(H15<>"",I15<>"",I15<>0),H15/I15,"") -> 0.01
E16: =IF(AND(C16<>"",D16<>"",D16<>0),C16/D16,"") | G16: Lapicero | H16: 2 | I16: 100 | J16: =IF(AND(H16<>"",I16<>"",I16<>0),H16/I16,"") -> 0.02
B18: 📦 TOTAL costo variable por unidad | E18: =SUM(E7:E16) -> 1.8616667 | G18: 🏢 TOTAL costo fijo por pedido | J18: =SUM(J7:J16) -> 582.81
B21: 📦 PASO 3 — ¿Cuántos pedidos haces al mes? (para repartir los gastos fijos entre cada venta)
B22: 🔢 Número de pedidos al mes: | C22: 300 | D22: ← Escribe aquí cuántos pedidos vendes en un mes normal
B25: ✅ RESULTADO — Tu Costo Unitario Total por producto
B26: 🧮 COSTO UNITARIO = costo variable + (costo fijo ÷ pedidos al mes) | E26: =(E18+J18)/C22 -> 1.9489056
B29: 💡 EJEMPLO EXPLICADO — ¿Cómo funciona este cálculo?
B30: Bolsas: compraste 1,000 por S/312 | E30: → cada bolsa te cuesta | G30: S/ 0.31
B31: Caja provincia: 100 por S/120 | E31: → cada caja te cuesta | G31: S/ 1.20
B32: Cinta: 50 por S/5 | E32: → cada rollo te cuesta | G32: S/ 0.10
B33: TOTAL costo variable por unidad: | G33: S/ 2.00
B34: Gastos fijos del mes: S/582 | E34: ÷ 300 pedidos al mes | G34: S/ 1.94 por pedido
B35: ► COSTO UNITARIO TOTAL: | E35: S/ 2.00 + S/ 1.94 | G35: 3.94
B38: 🔗 CONEXIÓN AUTOMÁTICA — Este valor pasa directo a la hoja INVENTARIO EN STOCK
B39: ✅ En la hoja INVENTARIO EN STOCK, la columna "📦 costo unitario" ya usa este resultado automáticamente.
B40: ➡ Si cambias cualquier costo aquí, la ganancia y el precio de venta se actualizan solos en toda la planilla.
B43: ⭐ TIPS PARA EMPRENDEDORAS
B44: 🟡 Celdas AMARILLAS → Son las que TÚ llenas. Cambia los valores según tus gastos reales.
B45: 🔵 Celdas AZULES / ROJAS → Se calculan solas. ¡No las toques!
B46: 📦 Costos Variables = materiales que usas para cada pedido (bolsas, cajas, cinta, etc.)
B47: 🏢 Costos Fijos = gastos del negocio que pagas siempre (luz, internet, sueldo, etc.) — se dividen entre todos tus pedidos.
B48: 📊 Pedidos al mes = ¿cuántos paquetes/ventas haces en un mes? Pon un número promedio.
B49: 💡 Actualiza esta hoja cuando cambien tus precios de insumos o tus gastos mensuales.
B51: =#VALUE! -> #VALUE!

Sheet INVENTARIO EN STOCK
B1: 💰 PRECIOS BASE — Tu Menú Permanente de Productos
B2: 📌 Configura aquí tus productos UNA VEZ. NO la uses para registrar ventas — para eso usa 📊 CALCULADORA CAMPAÑA
B3: ⚙️ COMISIÓN GLOBAL (se toma de INICIO): | C3: ='🏠 INICIO'!C8 -> 0.1 | E3: ← Cámbialo en hoja INICIO
B4: 🔵 Tú ingresas | E4: ⚫ Calculado auto | H4: 🟡 % comisión editable | L4: 🟢 Ganancia real
B5: # | C5: CATÁLOGO | D5: PRODUCTO | E5: 💰 COSTO (lo que pagas) | F5: 📦 Costo unitario (desde hoja COSTO UNITARIO 🔗) | G5: 📥 INVERSIÓN (costo+empaque) | H5: 📈 % MARGEN utilidad (30%) | I5: 🏷️ PRECIO VENTA (calculado) | J5: 💸 COSTO TOTAL | L5: 💵 MARGEN S/ (ganancia bruta) | M5: 🏆 COMISIÓN ventas % | N5: 💎 COMISIÓN S/ | O5: ✅ GANANCIA NETA
B6: 1 | C6: NATURA | D6: Crema tododia ciruela y flor de vainila | E6: 21 | F6: ='COSTO UNITARIO'!#REF! -> #REF! | G6: =E6+F6 -> #REF! | H6: 0.2 | I6: =IF(G6<>"",G6/(1-H6)/(1-M6),"") -> #REF! | J6: =IF(G6<>"",G6,"") -> #REF! | L6: =IF(I6<>"",(G6/(1-H6))-G6,"") -> #REF! | M6: 0.1 | N6: =IF(I6<>"",I6-(G6/(1-H6)),"") -> #REF! | O6: =IF(I6<>"",L6,"") -> #REF!
B7: 2 | C7: CYZONE | D7: Mini Chic Colonia | E7: 15 | F7: ='COSTO UNITARIO'!#REF! -> #REF! | G7: =E7+F7 -> #REF! | H7: 0.2 | I7: =IF(G7<>"",G7/(1-H7)/(1-M7),"") -> #REF! | J7: =IF(G7<>"",G7,"") -> #REF! | L7: =IF(I7<>"",(G7/(1-H7))-G7,"") -> #REF! | M7: 0.1 | N7: =IF(I7<>"",I7-(G7/(1-H7)),"") -> #REF! | O7: =IF(I7<>"",L7,"") -> #REF!
B8: 3 | C8: ESIKA | D8: Expression Magic | F8: ='COSTO UNITARIO'!#REF! -> #REF! | G8: =E8+F8 -> #REF! | H8: 0.2 | I8: =IF(G8<>"",G8/(1-H8)/(1-M8),"") -> #REF! | J8: =IF(G8<>"",G8,"") -> #REF! | L8: =IF(I8<>"",(G8/(1-H8))-G8,"") -> #REF! | M8: ='🏠 INICIO'!C8 -> 0.1 | N8: =IF(I8<>"",I8-(G8/(1-H8)),"") -> #REF! | O8: =IF(I8<>"",L8,"") -> #REF!
B9: 4 | C9: NATURA | D9: Perfume Tododia Floral | F9: ='COSTO UNITARIO'!#REF! -> #REF! | G9: =E9+F9 -> #REF! | H9: 0.25 | I9: =IF(G9<>"",G9/(1-H9)/(1-M9),"") -> #REF! | J9: =IF(G9<>"",G9,"") -> #REF! | L9: =IF(I9<>"",(G9/(1-H9))-G9,"") -> #REF! | M9: ='🏠 INICIO'!C8 -> 0.1 | N9: =IF(I9<>"",I9-(G9/(1-H9)),"") -> #REF! | O9: =IF(I9<>"",L9,"") -> #REF!
B10: 5 | C10: AVON | D10: Anew Gold Crema | F10: ='COSTO UNITARIO'!#REF! -> #REF! | G10: =E10+F10 -> #REF! | H10: 0.3 | I10: =IF(G10<>"",G10/(1-H10)/(1-M10),"") -> #REF! | J10: =IF(G10<>"",G10,"") -> #REF! | L10: =IF(I10<>"",(G10/(1-H10))-G10,"") -> #REF! | M10: ='🏠 INICIO'!C8 -> 0.1 | N10: =IF(I10<>"",I10-(G10/(1-H10)),"") -> #REF! | O10: =IF(I10<>"",L10,"") -> #REF!
B11: 6 | C11: ORIFLAME | F11: ='COSTO UNITARIO'!#REF! -> #REF! | G11: =E11+F11 -> #REF! | H11: 0.3 | I11: =IF(G11<>"",G11/(1-H11)/(1-M11),"") -> #REF! | J11: =IF(G11<>"",G11,"") -> #REF! | L11: =IF(I11<>"",(G11/(1-H11))-G11,"") -> #REF! | M11: ='🏠 INICIO'!C8 -> 0.1 | N11: =IF(I11<>"",I11-(G11/(1-H11)),"") -> #REF! | O11: =IF(I11<>"",L11,"") -> #REF!
B12: 7 | C12: FARMASI | F12: ='COSTO UNITARIO'!#REF! -> #REF! | G12: =E12+F12 -> #REF! | H12: 0.3 | I12: =IF(G12<>"",G12/(1-H12)/(1-M12),"") -> #REF! | J12: =IF(G12<>"",G12,"") -> #REF! | L12: =IF(I12<>"",(G12/(1-H12))-G12,"") -> #REF! | M12: ='🏠 INICIO'!C8 -> 0.1 | N12: =IF(I12<>"",I12-(G12/(1-H12)),"") -> #REF! | O12: =IF(I12<>"",L12,"") -> #REF!
B13: 8 | C13: YANBAL | F13: ='COSTO UNITARIO'!#REF! -> #REF! | G13: =E13+F13 -> #REF! | H13: 0.35 | I13: =IF(G13<>"",G13/(1-H13)/(1-M13),"") -> #REF! | J13: =IF(G13<>"",G13,"") -> #REF! | L13: =IF(I13<>"",(G13/(1-H13))-G13,"") -> #REF! | M13: ='🏠 INICIO'!C8 -> 0.1 | N13: =IF(I13<>"",I13-(G13/(1-H13)),"") -> #REF! | O13: =IF(I13<>"",L13,"") -> #REF!
B14: 9 | C14: YANBAL | F14: ='COSTO UNITARIO'!#REF! -> #REF! | G14: =E14+F14 -> #REF! | H14: 0.35 | I14: =IF(G14<>"",G14/(1-H14)/(1-M14),"") -> #REF! | J14: =IF(G14<>"",G14,"") -> #REF! | L14: =IF(I14<>"",(G14/(1-H14))-G14,"") -> #REF! | M14: ='🏠 INICIO'!C8 -> 0.1 | N14: =IF(I14<>"",I14-(G14/(1-H14)),"") -> #REF! | O14: =IF(I14<>"",L14,"") -> #REF!
B15: 10 | C15: ESIKA | F15: ='COSTO UNITARIO'!#REF! -> #REF! | G15: =E15+F15 -> #REF! | H15: 0.35 | I15: =IF(G15<>"",G15/(1-H15)/(1-M15),"") -> #REF! | J15: =IF(G15<>"",G15,"") -> #REF! | L15: =IF(I15<>"",(G15/(1-H15))-G15,"") -> #REF! | M15: ='🏠 INICIO'!C8 -> 0.1 | N15: =IF(I15<>"",I15-(G15/(1-H15)),"") -> #REF! | O15: =IF(I15<>"",L15,"") -> #REF!
B16: 11 | C16: CYZONE | F16: ='COSTO UNITARIO'!#REF! -> #REF! | G16: =E16+F16 -> #REF! | H16: 0.35 | I16: =IF(G16<>"",G16/(1-H16)/(1-M16),"") -> #REF! | J16: =IF(G16<>"",G16,"") -> #REF! | L16: =IF(I16<>"",(G16/(1-H16))-G16,"") -> #REF! | M16: ='🏠 INICIO'!C8 -> 0.1 | N16: =IF(I16<>"",I16-(G16/(1-H16)),"") -> #REF! | O16: =IF(I16<>"",L16,"") -> #REF!
B17: 12 | C17: NATURA | F17: ='COSTO UNITARIO'!#REF! -> #REF! | G17: =E17+F17 -> #REF! | H17: 0.35 | I17: =IF(G17<>"",G17/(1-H17)/(1-M17),"") -> #REF! | J17: =IF(G17<>"",G17,"") -> #REF! | L17: =IF(I17<>"",(G17/(1-H17))-G17,"") -> #REF! | M17: ='🏠 INICIO'!C8 -> 0.1 | N17: =IF(I17<>"",I17-(G17/(1-H17)),"") -> #REF! | O17: =IF(I17<>"",L17,"") -> #REF!
B18: 13 | C18: AVON | F18: ='COSTO UNITARIO'!#REF! -> #REF! | G18: =E18+F18 -> #REF! | H18: 0.3 | I18: =IF(G18<>"",G18/(1-H18)/(1-M18),"") -> #REF! | J18: =IF(G18<>"",G18,"") -> #REF! | L18: =IF(I18<>"",(G18/(1-H18))-G18,"") -> #REF! | M18: ='🏠 INICIO'!C8 -> 0.1 | N18: =IF(I18<>"",I18-(G18/(1-H18)),"") -> #REF! | O18: =IF(I18<>"",L18,"") -> #REF!
B19: 14 | C19: FARMASI | F19: ='COSTO UNITARIO'!#REF! -> #REF! | G19: =E19+F19 -> #REF! | H19: 0.3 | I19: =IF(G19<>"",G19/(1-H19)/(1-M19),"") -> #REF! | J19: =IF(G19<>"",G19,"") -> #REF! | L19: =IF(I19<>"",(G19/(1-H19))-G19,"") -> #REF! | M19: ='🏠 INICIO'!C8 -> 0.1 | N19: =IF(I19<>"",I19-(G19/(1-H19)),"") -> #REF! | O19: =IF(I19<>"",L19,"") -> #REF!
B20: 15 | C20: LBEL | F20: ='COSTO UNITARIO'!#REF! -> #REF! | G20: =E20+F20 -> #REF! | H20: 0.35 | I20: =IF(G20<>"",G20/(1-H20)/(1-M20),"") -> #REF! | J20: =IF(G20<>"",G20,"") -> #REF! | L20: =IF(I20<>"",(G20/(1-H20))-G20,"") -> #REF! | M20: ='🏠 INICIO'!C8 -> 0.1 | N20: =IF(I20<>"",I20-(G20/(1-H20)),"") -> #REF! | O20: =IF(I20<>"",L20,"") -> #REF!
B21: 16 | C21: LBEL | F21: ='COSTO UNITARIO'!#REF! -> #REF! | G21: =E21+F21 -> #REF! | H21: 0.35 | I21: =IF(G21<>"",G21/(1-H21)/(1-M21),"") -> #REF! | J21: =IF(G21<>"",G21,"") -> #REF! | L21: =IF(I21<>"",(G21/(1-H21))-G21,"") -> #REF! | M21: ='🏠 INICIO'!C8 -> 0.1 | N21: =IF(I21<>"",I21-(G21/(1-H21)),"") -> #REF! | O21: =IF(I21<>"",L21,"") -> #REF!
B22: 17 | C22: ORIFLAME | F22: ='COSTO UNITARIO'!#REF! -> #REF! | G22: =E22+F22 -> #REF! | H22: 0.3 | I22: =IF(G22<>"",G22/(1-H22)/(1-M22),"") -> #REF! | J22: =IF(G22<>"",G22,"") -> #REF! | L22: =IF(I22<>"",(G22/(1-H22))-G22,"") -> #REF! | M22: ='🏠 INICIO'!C8 -> 0.1 | N22: =IF(I22<>"",I22-(G22/(1-H22)),"") -> #REF! | O22: =IF(I22<>"",L22,"") -> #REF!
B23: 18 | C23: YANBAL | F23: ='COSTO UNITARIO'!#REF! -> #REF! | G23: =E23+F23 -> #REF! | H23: 0.36 | I23: =IF(G23<>"",G23/(1-H23)/(1-M23),"") -> #REF! | J23: =IF(G23<>"",G23,"") -> #REF! | L23: =IF(I23<>"",(G23/(1-H23))-G23,"") -> #REF! | M23: ='🏠 INICIO'!C8 -> 0.1 | N23: =IF(I23<>"",I23-(G23/(1-H23)),"") -> #REF! | O23: =IF(I23<>"",L23,"") -> #REF!
B24: 19 | C24: CYZONE | F24: ='COSTO UNITARIO'!#REF! -> #REF! | G24: =E24+F24 -> #REF! | H24: 0.35 | I24: =IF(G24<>"",G24/(1-H24)/(1-M24),"") -> #REF! | J24: =IF(G24<>"",G24,"") -> #REF! | L24: =IF(I24<>"",(G24/(1-H24))-G24,"") -> #REF! | M24: ='🏠 INICIO'!C8 -> 0.1 | N24: =IF(I24<>"",I24-(G24/(1-H24)),"") -> #REF! | O24: =IF(I24<>"",L24,"") -> #REF!
B25: 20 | C25: ESIKA | F25: ='COSTO UNITARIO'!#REF! -> #REF! | G25: =E25+F25 -> #REF! | H25: 0.35 | I25: =IF(G25<>"",G25/(1-H25)/(1-M25),"") -> #REF! | J25: =IF(G25<>"",G25,"") -> #REF! | L25: =IF(I25<>"",(G25/(1-H25))-G25,"") -> #REF! | M25: ='🏠 INICIO'!C8 -> 0.1 | N25: =IF(I25<>"",I25-(G25/(1-H25)),"") -> #REF! | O25: =IF(I25<>"",L25,"") -> #REF!
B26: 21 | F26: ='COSTO UNITARIO'!#REF! -> #REF! | G26: =IF(E26<>"",E26+F26,"") | I26: =IF(G26<>"",G26/(1-H26)/(1-M26),"") | J26: =IF(G26<>"",G26,"") | L26: =IF(I26<>"",(G26/(1-H26))-G26,"") | M26: ='🏠 INICIO'!C8 -> 0.1 | N26: =IF(I26<>"",I26-(G26/(1-H26)),"") | O26: =IF(I26<>"",L26,"")
B27: 22 | F27: ='COSTO UNITARIO'!#REF! -> #REF! | G27: =IF(E27<>"",E27+F27,"") | I27: =IF(G27<>"",G27/(1-H27)/(1-M27),"") | J27: =IF(G27<>"",G27,"") | L27: =IF(I27<>"",(G27/(1-H27))-G27,"") | M27: ='🏠 INICIO'!C8 -> 0.1 | N27: =IF(I27<>"",I27-(G27/(1-H27)),"") | O27: =IF(I27<>"",L27,"")
B28: 23 | F28: ='COSTO UNITARIO'!#REF! -> #REF! | G28: =IF(E28<>"",E28+F28,"") | I28: =IF(G28<>"",G28/(1-H28)/(1-M28),"") | J28: =IF(G28<>"",G28,"") | L28: =IF(I28<>"",(G28/(1-H28))-G28,"") | M28: ='🏠 INICIO'!C8 -> 0.1 | N28: =IF(I28<>"",I28-(G28/(1-H28)),"") | O28: =IF(I28<>"",L28,"")
B29: 24 | F29: ='COSTO UNITARIO'!#REF! -> #REF! | G29: =IF(E29<>"",E29+F29,"") | I29: =IF(G29<>"",G29/(1-H29)/(1-M29),"") | J29: =IF(G29<>"",G29,"") | L29: =IF(I29<>"",(G29/(1-H29))-G29,"") | M29: ='🏠 INICIO'!C8 -> 0.1 | N29: =IF(I29<>"",I29-(G29/(1-H29)),"") | O29: =IF(I29<>"",L29,"")
B30: 25 | F30: ='COSTO UNITARIO'!#REF! -> #REF! | G30: =IF(E30<>"",E30+F30,"") | I30: =IF(G30<>"",G30/(1-H30)/(1-M30),"") | J30: =IF(G30<>"",G30,"") | L30: =IF(I30<>"",(G30/(1-H30))-G30,"") | M30: ='🏠 INICIO'!C8 -> 0.1 | N30: =IF(I30<>"",I30-(G30/(1-H30)),"") | O30: =IF(I30<>"",L30,"")
B31: 26 | F31: ='COSTO UNITARIO'!#REF! -> #REF! | G31: =IF(E31<>"",E31+F31,"") | I31: =IF(G31<>"",G31/(1-H31)/(1-M31),"") | J31: =IF(G31<>"",G31,"") | L31: =IF(I31<>"",(G31/(1-H31))-G31,"") | M31: ='🏠 INICIO'!C8 -> 0.1 | N31: =IF(I31<>"",I31-(G31/(1-H31)),"") | O31: =IF(I31<>"",L31,"")
B32: 27 | F32: ='COSTO UNITARIO'!#REF! -> #REF! | G32: =IF(E32<>"",E32+F32,"") | I32: =IF(G32<>"",G32/(1-H32)/(1-M32),"") | J32: =IF(G32<>"",G32,"") | L32: =IF(I32<>"",(G32/(1-H32))-G32,"") | M32: ='🏠 INICIO'!C8 -> 0.1 | N32: =IF(I32<>"",I32-(G32/(1-H32)),"") | O32: =IF(I32<>"",L32,"")
B33: 28 | F33: ='COSTO UNITARIO'!#REF! -> #REF! | G33: =IF(E33<>"",E33+F33,"") | I33: =IF(G33<>"",G33/(1-H33)/(1-M33),"") | J33: =IF(G33<>"",G33,"") | L33: =IF(I33<>"",(G33/(1-H33))-G33,"") | M33: ='🏠 INICIO'!C8 -> 0.1 | N33: =IF(I33<>"",I33-(G33/(1-H33)),"") | O33: =IF(I33<>"",L33,"")
B34: 29 | F34: ='COSTO UNITARIO'!#REF! -> #REF! | G34: =IF(E34<>"",E34+F34,"") | I34: =IF(G34<>"",G34/(1-H34)/(1-M34),"") | J34: =IF(G34<>"",G34,"") | L34: =IF(I34<>"",(G34/(1-H34))-G34,"") | M34: ='🏠 INICIO'!C8 -> 0.1 | N34: =IF(I34<>"",I34-(G34/(1-H34)),"") | O34: =IF(I34<>"",L34,"")
B35: 30 | F35: ='COSTO UNITARIO'!#REF! -> #REF! | G35: =IF(E35<>"",E35+F35,"") | I35: =IF(G35<>"",G35/(1-H35)/(1-M35),"") | J35: =IF(G35<>"",G35,"") | L35: =IF(I35<>"",(G35/(1-H35))-G35,"") | M35: ='🏠 INICIO'!C8 -> 0.1 | N35: =IF(I35<>"",I35-(G35/(1-H35)),"") | O35: =IF(I35<>"",L35,"")
B36: 31 | F36: ='COSTO UNITARIO'!#REF! -> #REF! | G36: =IF(E36<>"",E36+F36,"") | I36: =IF(G36<>"",G36/(1-H36)/(1-M36),"") | J36: =IF(G36<>"",G36,"") | L36: =IF(I36<>"",(G36/(1-H36))-G36,"") | M36: ='🏠 INICIO'!C8 -> 0.1 | N36: =IF(I36<>"",I36-(G36/(1-H36)),"") | O36: =IF(I36<>"",L36,"")
B37: 32 | F37: ='COSTO UNITARIO'!#REF! -> #REF! | G37: =IF(E37<>"",E37+F37,"") | I37: =IF(G37<>"",G37/(1-H37)/(1-M37),"") | J37: =IF(G37<>"",G37,"") | L37: =IF(I37<>"",(G37/(1-H37))-G37,"") | M37: ='🏠 INICIO'!C8 -> 0.1 | N37: =IF(I37<>"",I37-(G37/(1-H37)),"") | O37: =IF(I37<>"",L37,"")
B38: 33 | F38: ='COSTO UNITARIO'!#REF! -> #REF! | G38: =IF(E38<>"",E38+F38,"") | I38: =IF(G38<>"",G38/(1-H38)/(1-M38),"") | J38: =IF(G38<>"",G38,"") | L38: =IF(I38<>"",(G38/(1-H38))-G38,"") | M38: ='🏠 INICIO'!C8 -> 0.1 | N38: =IF(I38<>"",I38-(G38/(1-H38)),"") | O38: =IF(I38<>"",L38,"")
B39: 34 | F39: ='COSTO UNITARIO'!#REF! -> #REF! | G39: =IF(E39<>"",E39+F39,"") | I39: =IF(G39<>"",G39/(1-H39)/(1-M39),"") | J39: =IF(G39<>"",G39,"") | L39: =IF(I39<>"",(G39/(1-H39))-G39,"") | M39: ='🏠 INICIO'!C8 -> 0.1 | N39: =IF(I39<>"",I39-(G39/(1-H39)),"") | O39: =IF(I39<>"",L39,"")
B40: 35 | F40: ='COSTO UNITARIO'!#REF! -> #REF! | G40: =IF(E40<>"",E40+F40,"") | I40: =IF(G40<>"",G40/(1-H40)/(1-M40),"") | J40: =IF(G40<>"",G40,"") | L40: =IF(I40<>"",(G40/(1-H40))-G40,"") | M40: ='🏠 INICIO'!C8 -> 0.1 | N40: =IF(I40<>"",I40-(G40/(1-H40)),"") | O40: =IF(I40<>"",L40,"")
...

Sheet 📊 CALCULADORA CAMPAÑA
B1: 📊 CALCULADORA DE CAMPAÑA — Registra lo que vendiste esta campaña | P1: #VALUE!
B2: ✅ ÚSALA CADA CAMPAÑA (cada ~3 semanas). Diferencia con PRECIOS BASE: aquí registras ventas reales, allá defines precios permanentes.
B3: CAMPAÑA N°: | C3: 1 | E3: MES: | F3: ENERO | H3: % COMISIÓN: | I3: ='🏠 INICIO'!C8 -> 0.1 | J3: ← Edita en hoja INICIO · Aquí se actualiza solo
B5: # | C5: MES | D5: CATÁLOGO | E5: PRODUCTO | F5: 💰 COSTO Producto | G5: 📦 COSTO UNITARIO | H5: 📥 COSTO TOTAL | I5: 📈 % Ganancia | J5: 🏷️ PRECIO Venta | K5: 💸 COSTO Total | L5: 💵 MARGEN S/ | M5: 🏆 COM. % | N5: 💎 COM. S/ | O5: ✅ GANANCIA NETA
B6: 1 | C6: JUNIO | D6: NATURA | E6: Crema Corporal Tododia | F6: 20 | G6: 3 | H6: =IF(F6<>"",F6+G6,"") -> 23 | I6: 0.36 | J6: =IF(AND(H6<>"",I6<1),H6/(1-I6),"") -> 35.9375 | K6: =IF(F6<>"",F6+G6,"") -> 23 | L6: =IF(J6<>"",J6-K6,"") -> 12.9375 | M6: ='🏠 INICIO'!C8 -> 0.1 | N6: =IF(J6<>"",J6*M6,"") -> 3.59375 | O6: =IF(L6<>"",L6-N6,"") -> 9.34375
B7: 2 | C7: JUNIO | D7: ESIKA | E7: Expression Magic | F7: 21 | G7: 3 | H7: =IF(F7<>"",F7+G7,"") -> 24 | I7: 0.35 | J7: =IF(AND(H7<>"",I7<1),H7/(1-I7),"") -> 36.923077 | K7: =IF(F7<>"",F7+G7,"") -> 24 | L7: =IF(J7<>"",J7-K7,"") -> 12.923077 | M7: ='🏠 INICIO'!C8 -> 0.1 | N7: =IF(J7<>"",J7*M7,"") -> 3.6923077 | O7: =IF(L7<>"",L7-N7,"") -> 9.2307692
B8: 3 | C8: JUNIO | D8: ESIKA | E8: Mini Chic Colonia | F8: 12 | G8: 3 | H8: =IF(F8<>"",F8+G8,"") -> 15 | I8: 0.3 | J8: =IF(AND(H8<>"",I8<1),H8/(1-I8),"") -> 21.428571 | K8: =IF(F8<>"",F8+G8,"") -> 15 | L8: =IF(J8<>"",J8-K8,"") -> 6.4285714 | M8: ='🏠 INICIO'!C8 -> 0.1 | N8: =IF(J8<>"",J8*M8,"") -> 2.1428571 | O8: =IF(L8<>"",L8-N8,"") -> 4.2857143
B9: 4 | C9: JUNIO | D9: YANBAL | E9: Kit Perfume Dulce Vanidad | F9: 65 | G9: 3 | H9: =IF(F9<>"",F9+G9,"") -> 68 | I9: 0.36 | J9: =IF(AND(H9<>"",I9<1),H9/(1-I9),"") -> 106.25 | K9: =IF(F9<>"",F9+G9,"") -> 68 | L9: =IF(J9<>"",J9-K9,"") -> 38.25 | M9: ='🏠 INICIO'!C8 -> 0.1 | N9: =IF(J9<>"",J9*M9,"") -> 10.625 | O9: =IF(L9<>"",L9-N9,"") -> 27.625
B10: 5 | C10: ENERO | D10: NATURA | E10: Beijo Humor Colonia | F10: 45 | G10: 3 | H10: =IF(F10<>"",F10+G10,"") -> 48 | I10: 0.35 | J10: =IF(AND(H10<>"",I10<1),H10/(1-I10),"") -> 73.846154 | K10: =IF(F10<>"",F10+G10,"") -> 48 | L10: =IF(J10<>"",J10-K10,"") -> 25.846154 | M10: ='🏠 INICIO'!C8 -> 0.1 | N10: =IF(J10<>"",J10*M10,"") -> 7.3846154 | O10: =IF(L10<>"",L10-N10,"") -> 18.461538
B11: 6 | C11: ENERO | D11: CYZONE | E11: Set de Brochas 5 piezas | F11: 30 | G11: 3 | H11: =IF(F11<>"",F11+G11,"") -> 33 | I11: 0.35 | J11: =IF(AND(H11<>"",I11<1),H11/(1-I11),"") -> 50.769231 | K11: =IF(F11<>"",F11+G11,"") -> 33 | L11: =IF(J11<>"",J11-K11,"") -> 17.769231 | M11: ='🏠 INICIO'!C8 -> 0.1 | N11: =IF(J11<>"",J11*M11,"") -> 5.0769231 | O11: =IF(L11<>"",L11-N11,"") -> 12.692308
B12: 7 | C12: ENERO | D12: AVON | E12: Anew Gold Crema Facial | F12: 35.5 | G12: 3 | H12: =IF(F12<>"",F12+G12,"") -> 38.5 | I12: 0.3 | J12: =IF(AND(H12<>"",I12<1),H12/(1-I12),"") -> 55 | K12: =IF(F12<>"",F12+G12,"") -> 38.5 | L12: =IF(J12<>"",J12-K12,"") -> 16.5 | M12: ='🏠 INICIO'!C8 -> 0.1 | N12: =IF(J12<>"",J12*M12,"") -> 5.5 | O12: =IF(L12<>"",L12-N12,"") -> 11
B13: 8 | C13: ENERO | D13: ESIKA | E13: Color Fix Barra Vino | F13: 18 | G13: 3 | H13: =IF(F13<>"",F13+G13,"") -> 21 | I13: 0.35 | J13: =IF(AND(H13<>"",I13<1),H13/(1-I13),"") -> 32.307692 | K13: =IF(F13<>"",F13+G13,"") -> 21 | L13: =IF(J13<>"",J13-K13,"") -> 11.307692 | M13: ='🏠 INICIO'!C8 -> 0.1 | N13: =IF(J13<>"",J13*M13,"") -> 3.2307692 | O13: =IF(L13<>"",L13-N13,"") -> 8.0769231
B14: 9 | C14: ENERO | D14: ORIFLAME | E14: Giordani Gold Serum | F14: 51 | G14: 3 | H14: =IF(F14<>"",F14+G14,"") -> 54 | I14: 0.3 | J14: =IF(AND(H14<>"",I14<1),H14/(1-I14),"") -> 77.142857 | K14: =IF(F14<>"",F14+G14,"") -> 54 | L14: =IF(J14<>"",J14-K14,"") -> 23.142857 | M14: ='🏠 INICIO'!C8 -> 0.1 | N14: =IF(J14<>"",J14*M14,"") -> 7.7142857 | O14: =IF(L14<>"",L14-N14,"") -> 15.428571
B15: 10 | C15: ENERO | D15: YANBAL | E15: Argollas Spiga Perle | F15: 55 | G15: 3 | H15: =IF(F15<>"",F15+G15,"") -> 58 | I15: 0.35 | J15: =IF(AND(H15<>"",I15<1),H15/(1-I15),"") -> 89.230769 | K15: =IF(F15<>"",F15+G15,"") -> 58 | L15: =IF(J15<>"",J15-K15,"") -> 31.230769 | M15: ='🏠 INICIO'!C8 -> 0.1 | N15: =IF(J15<>"",J15*M15,"") -> 8.9230769 | O15: =IF(L15<>"",L15-N15,"") -> 22.307692
B16: 11 | C16: ENERO | D16: FARMASI | E16: Labial Matte Stay 24h | F16: 18 | G16: 3 | H16: =IF(F16<>"",F16+G16,"") -> 21 | I16: 0.3 | J16: =IF(AND(H16<>"",I16<1),H16/(1-I16),"") -> 30 | K16: =IF(F16<>"",F16+G16,"") -> 21 | L16: =IF(J16<>"",J16-K16,"") -> 9 | M16: ='🏠 INICIO'!C8 -> 0.1 | N16: =IF(J16<>"",J16*M16,"") -> 3 | O16: =IF(L16<>"",L16-N16,"") -> 6
B17: 12 | C17: ENERO | D17: LBEL | E17: Serum Effet Parfait | F17: 59 | G17: 3 | H17: =IF(F17<>"",F17+G17,"") -> 62 | I17: 0.35 | J17: =IF(AND(H17<>"",I17<1),H17/(1-I17),"") -> 95.384615 | K17: =IF(F17<>"",F17+G17,"") -> 62 | L17: =IF(J17<>"",J17-K17,"") -> 33.384615 | M17: ='🏠 INICIO'!C8 -> 0.1 | N17: =IF(J17<>"",J17*M17,"") -> 9.5384615 | O17: =IF(L17<>"",L17-N17,"") -> 23.846154
B18: 13 | C18: ENERO | D18: CYZONE | E18: Pink Crush Colonia | F18: 28 | G18: 3 | H18: =IF(F18<>"",F18+G18,"") -> 31 | I18: 0.35 | J18: =IF(AND(H18<>"",I18<1),H18/(1-I18),"") -> 47.692308 | K18: =IF(F18<>"",F18+G18,"") -> 31 | L18: =IF(J18<>"",J18-K18,"") -> 16.692308 | M18: ='🏠 INICIO'!C8 -> 0.1 | N18: =IF(J18<>"",J18*M18,"") -> 4.7692308 | O18: =IF(L18<>"",L18-N18,"") -> 11.923077
B19: 14 | C19: ENERO | D19: NATURA | E19: Perfume Tododia Floral | F19: 34 | G19: 3 | H19: =IF(F19<>"",F19+G19,"") -> 37 | I19: 0.35 | J19: =IF(AND(H19<>"",I19<1),H19/(1-I19),"") -> 56.923077 | K19: =IF(F19<>"",F19+G19,"") -> 37 | L19: =IF(J19<>"",J19-K19,"") -> 19.923077 | M19: ='🏠 INICIO'!C8 -> 0.1 | N19: =IF(J19<>"",J19*M19,"") -> 5.6923077 | O19: =IF(L19<>"",L19-N19,"") -> 14.230769
B20: 15 | C20: ENERO | D20: ESIKA | E20: Rimel Esika Pro | F20: 22 | G20: 3 | H20: =IF(F20<>"",F20+G20,"") -> 25 | I20: 0.35 | J20: =IF(AND(H20<>"",I20<1),H20/(1-I20),"") -> 38.461538 | K20: =IF(F20<>"",F20+G20,"") -> 25 | L20: =IF(J20<>"",J20-K20,"") -> 13.461538 | M20: ='🏠 INICIO'!C8 -> 0.1 | N20: =IF(J20<>"",J20*M20,"") -> 3.8461538 | O20: =IF(L20<>"",L20-N20,"") -> 9.6153846
B21: 16 | H21: =IF(F21<>"",F21+G21,"") | J21: =IF(AND(H21<>"",I21<>0,I21<1),H21/(1-I21),"") | K21: =IF(F21<>"",F21+G21,"") | L21: =IF(J21<>"",J21-K21,"") | M21: ='🏠 INICIO'!C8 -> 0.1 | N21: =IF(J21<>"",J21*M21,"") | O21: =IF(L21<>"",L21-N21,"")
B22: 17 | H22: =IF(F22<>"",F22+G22,"") | J22: =IF(AND(H22<>"",I22<>0,I22<1),H22/(1-I22),"") | K22: =IF(F22<>"",F22+G22,"") | L22: =IF(J22<>"",J22-K22,"") | M22: ='🏠 INICIO'!C8 -> 0.1 | N22: =IF(J22<>"",J22*M22,"") | O22: =IF(L22<>"",L22-N22,"")
B23: 18 | H23: =IF(F23<>"",F23+G23,"") | J23: =IF(AND(H23<>"",I23<>0,I23<1),H23/(1-I23),"") | K23: =IF(F23<>"",F23+G23,"") | L23: =IF(J23<>"",J23-K23,"") | M23: ='🏠 INICIO'!C8 -> 0.1 | N23: =IF(J23<>"",J23*M23,"") | O23: =IF(L23<>"",L23-N23,"")
B24: 19 | H24: =IF(F24<>"",F24+G24,"") | J24: =IF(AND(H24<>"",I24<>0,I24<1),H24/(1-I24),"") | K24: =IF(F24<>"",F24+G24,"") | L24: =IF(J24<>"",J24-K24,"") | M24: ='🏠 INICIO'!C8 -> 0.1 | N24: =IF(J24<>"",J24*M24,"") | O24: =IF(L24<>"",L24-N24,"")
B25: 20 | H25: =IF(F25<>"",F25+G25,"") | J25: =IF(AND(H25<>"",I25<>0,I25<1),H25/(1-I25),"") | K25: =IF(F25<>"",F25+G25,"") | L25: =IF(J25<>"",J25-K25,"") | M25: ='🏠 INICIO'!C8 -> 0.1 | N25: =IF(J25<>"",J25*M25,"") | O25: =IF(L25<>"",L25-N25,"")
B26: 21 | H26: =IF(F26<>"",F26+G26,"") | J26: =IF(AND(H26<>"",I26<>0,I26<1),H26/(1-I26),"") | K26: =IF(F26<>"",F26+G26,"") | L26: =IF(J26<>"",J26-K26,"") | M26: ='🏠 INICIO'!C8 -> 0.1 | N26: =IF(J26<>"",J26*M26,"") | O26: =IF(L26<>"",L26-N26,"")
B27: 22 | H27: =IF(F27<>"",F27+G27,"") | J27: =IF(AND(H27<>"",I27<>0,I27<1),H27/(1-I27),"") | K27: =IF(F27<>"",F27+G27,"") | L27: =IF(J27<>"",J27-K27,"") | M27: ='🏠 INICIO'!C8 -> 0.1 | N27: =IF(J27<>"",J27*M27,"") | O27: =IF(L27<>"",L27-N27,"")
B28: 23 | H28: =IF(F28<>"",F28+G28,"") | J28: =IF(AND(H28<>"",I28<>0,I28<1),H28/(1-I28),"") | K28: =IF(F28<>"",F28+G28,"") | L28: =IF(J28<>"",J28-K28,"") | M28: ='🏠 INICIO'!C8 -> 0.1 | N28: =IF(J28<>"",J28*M28,"") | O28: =IF(L28<>"",L28-N28,"")
B29: 24 | H29: =IF(F29<>"",F29+G29,"") | J29: =IF(AND(H29<>"",I29<>0,I29<1),H29/(1-I29),"") | K29: =IF(F29<>"",F29+G29,"") | L29: =IF(J29<>"",J29-K29,"") | M29: ='🏠 INICIO'!C8 -> 0.1 | N29: =IF(J29<>"",J29*M29,"") | O29: =IF(L29<>"",L29-N29,"")
B30: 25 | H30: =IF(F30<>"",F30+G30,"") | J30: =IF(AND(H30<>"",I30<>0,I30<1),H30/(1-I30),"") | K30: =IF(F30<>"",F30+G30,"") | L30: =IF(J30<>"",J30-K30,"") | M30: ='🏠 INICIO'!C8 -> 0.1 | N30: =IF(J30<>"",J30*M30,"") | O30: =IF(L30<>"",L30-N30,"")
B31: 26 | H31: =IF(F31<>"",F31+G31,"") | J31: =IF(AND(H31<>"",I31<>0,I31<1),H31/(1-I31),"") | K31: =IF(F31<>"",F31+G31,"") | L31: =IF(J31<>"",J31-K31,"") | M31: ='🏠 INICIO'!C8 -> 0.1 | N31: =IF(J31<>"",J31*M31,"") | O31: =IF(L31<>"",L31-N31,"")
B32: 27 | H32: =IF(F32<>"",F32+G32,"") | J32: =IF(AND(H32<>"",I32<>0,I32<1),H32/(1-I32),"") | K32: =IF(F32<>"",F32+G32,"") | L32: =IF(J32<>"",J32-K32,"") | M32: ='🏠 INICIO'!C8 -> 0.1 | N32: =IF(J32<>"",J32*M32,"") | O32: =IF(L32<>"",L32-N32,"")
B33: 28 | H33: =IF(F33<>"",F33+G33,"") | J33: =IF(AND(H33<>"",I33<>0,I33<1),H33/(1-I33),"") | K33: =IF(F33<>"",F33+G33,"") | L33: =IF(J33<>"",J33-K33,"") | M33: ='🏠 INICIO'!C8 -> 0.1 | N33: =IF(J33<>"",J33*M33,"") | O33: =IF(L33<>"",L33-N33,"")
B34: 29 | H34: =IF(F34<>"",F34+G34,"") | J34: =IF(AND(H34<>"",I34<>0,I34<1),H34/(1-I34),"") | K34: =IF(F34<>"",F34+G34,"") | L34: =IF(J34<>"",J34-K34,"") | M34: ='🏠 INICIO'!C8 -> 0.1 | N34: =IF(J34<>"",J34*M34,"") | O34: =IF(L34<>"",L34-N34,"")
B35: 30 | H35: =IF(F35<>"",F35+G35,"") | J35: =IF(AND(H35<>"",I35<>0,I35<1),H35/(1-I35),"") | K35: =IF(F35<>"",F35+G35,"") | L35: =IF(J35<>"",J35-K35,"") | M35: ='🏠 INICIO'!C8 -> 0.1 | N35: =IF(J35<>"",J35*M35,"") | O35: =IF(L35<>"",L35-N35,"")
B36: 31 | H36: =IF(F36<>"",F36+G36,"") | J36: =IF(AND(H36<>"",I36<>0,I36<1),H36/(1-I36),"") | K36: =IF(F36<>"",F36+G36,"") | L36: =IF(J36<>"",J36-K36,"") | M36: ='🏠 INICIO'!C8 -> 0.1 | N36: =IF(J36<>"",J36*M36,"") | O36: =IF(L36<>"",L36-N36,"")
B37: 32 | H37: =IF(F37<>"",F37+G37,"") | J37: =IF(AND(H37<>"",I37<>0,I37<1),H37/(1-I37),"") | K37: =IF(F37<>"",F37+G37,"") | L37: =IF(J37<>"",J37-K37,"") | M37: ='🏠 INICIO'!C8 -> 0.1 | N37: =IF(J37<>"",J37*M37,"") | O37: =IF(L37<>"",L37-N37,"")
B38: 33 | H38: =IF(F38<>"",F38+G38,"") | J38: =IF(AND(H38<>"",I38<>0,I38<1),H38/(1-I38),"") | K38: =IF(F38<>"",F38+G38,"") | L38: =IF(J38<>"",J38-K38,"") | M38: ='🏠 INICIO'!C8 -> 0.1 | N38: =IF(J38<>"",J38*M38,"") | O38: =IF(L38<>"",L38-N38,"")
B39: 34 | H39: =IF(F39<>"",F39+G39,"") | J39: =IF(AND(H39<>"",I39<>0,I39<1),H39/(1-I39),"") | K39: =IF(F39<>"",F39+G39,"") | L39: =IF(J39<>"",J39-K39,"") | M39: ='🏠 INICIO'!C8 -> 0.1 | N39: =IF(J39<>"",J39*M39,"") | O39: =IF(L39<>"",L39-N39,"")
B40: 35 | H40: =IF(F40<>"",F40+G40,"") | J40: =IF(AND(H40<>"",I40<>0,I40<1),H40/(1-I40),"") | K40: =IF(F40<>"",F40+G40,"") | L40: =IF(J40<>"",J40-K40,"") | M40: ='🏠 INICIO'!C8 -> 0.1 | N40: =IF(J40<>"",J40*M40,"") | O40: =IF(L40<>"",L40-N40,"")
B41: 36 | H41: =IF(F41<>"",F41+G41,"") | J41: =IF(AND(H41<>"",I41<>0,I41<1),H41/(1-I41),"") | K41: =IF(F41<>"",F41+G41,"") | L41: =IF(J41<>"",J41-K41,"") | M41: ='🏠 INICIO'!C8 -> 0.1 | N41: =IF(J41<>"",J41*M41,"") | O41: =IF(L41<>"",L41-N41,"")
...

Sheet 💵 CUANTO ME PAGO
B1: 💵 ¿CUÁNTO ME PAGO? — Tu Sueldo Real y Rentabilidad del Negocio
B2: 🎯 Revisa esta hoja al cerrar cada campaña. Aquí sabes si tu negocio te paga bien o solo estás trabajando gratis.
G3: ='📊 CALCULADORA CAMPAÑA'!O113 -> 0
B4: 📥 PASO 1: Ingresa los ingresos de tu campaña | F4: 🚦 ¿Es rentable tu negocio este mes?
B5: 💰 Total ventas cobradas (S/) | C5: 1500 | D5: ← ingresa el total cobrado en la campaña | F5: 🟢 Ganancia bruta > S/ 300 | G5: =IF(C21>=300,"✅ ¡Excelente campaña!","") -> ✅ ¡Excelente campaña!
B6: 💸 Comisión a vendedoras (10%) — se descuenta en gastos ↓ | C6: =ROUND(C5*0.1,2) -> 150 | D6: ← referencia — el descuento real está en Paso 2 | F6: 🟡 Ganancia bruta entre S/ 100 y S/ 299 | G6: =IF(AND(C21>=100,C21<300),"⚠️ Campaña regular, puedes mejorar","")
B7: ➕ Otros ingresos (bonos, etc.) | C7: 0 | D7: ← ingresa el total real de la campaña | F7: 🔴 Ganancia bruta < S/ 100 | G7: =IF(C21<100,"🚨 Ojo: casi no ganaste. Revisa tus precios","")
B8: 📊 TOTAL INGRESOS CAMPAÑA | C8: =C5+C7 -> 1500
F9: 🎯 Meta de sueldo mensual
B10: 📤 PASO 2: ¿Cuánto gastaste para vender? | F10: ¿Cuánto quieres ganar este mes? (S/) | G10: 750 | H10: ← ingresa tu meta
B11: 📦 Costo de productos (lo que le pagaste al catálogo) | C11: 600 | F11: Ventas necesarias para llegar a tu meta: | G11: =IF(AND(C5>0,C18>0),(G10/(C5-C18))*C5,"Llena los datos") -> 1500
B12: 💸 Comisión pagada a vendedoras (10%) | C12: =C6 -> 150 | D12: ← lo que le pagas a tu vendedora por vender
B13: 🚚 Delivery / envíos pagados | C13: 0 | F13: ¿Llegaste a tu meta este mes? | G13: =IF(C25>=G10,"✅ ¡Sí! Meta cumplida 🎉","❌ Aún no. Faltan S/ "&TEXT(G10-C25,"#,##0.00")) -> ❌ Aún no. Faltan S/ 375,000
B14: 📣 Publicidad (Redes, Impresiones) | C14: 0
B15: 📱 Internet / celular (parte del negocio) | C15: 0 | F15: 🏗️ Mis costos fijos mensuales
B16: 🛍️ Empaque y materiales | C16: 0 | F16: 💡 Luz / internet / celular | G16: 50
B17: 📋 Otros gastos del negocio | C17: 0 | F17: 📣 Publicidad mensual | G17: 100
B18: 📊 TOTAL GASTOS CAMPAÑA | C18: =SUM(C11:C17) -> 750 | F18: 🛍️ Empaque promedio mensual | G18: 30
F19: 📋 Otros costos fijos | G19: 0
B20: 🧮 PASO 3: ¿Cómo distribuir lo que te queda? | F20: 💸 TOTAL COSTOS FIJOS / MES: | G20: =SUM(G15:G18) -> 180
B21: 💵 Ganancia bruta (ventas − costos − comisión vendedora): | C21: =C8-C18 -> 750 | D21: Siempre se recomienda llegar o traspasar tu meta | F21: ⚡ Costo fijo por producto (aprox): | G21: =IF(C3<>0,G19/C3,"Llena productos") -> Llena productos
B22: 💡 Esta es tu ganancia REAL como dueña, ya descontando el pago a vendedoras. | F22: #VALUE!
B23: 🔁 Para reinvertir en próxima campaña (30%) | C23: =IF(C21>0,C21*0.3,0) -> 225
B24: 🛡️ Para fondo de emergencia / ahorro (20%) | C24: =IF(C21>0,C21*0.2,0) -> 150
B25: 💵 TU SUELDO como dueña — lo que te llevas (50%) | C25: =IF(C21>0,C21*0.5,0) -> 375
B27: 💡 Nota: Los % son una guía de referencia. Puedes ajustarlos según tu situación.

Sheet 🗂️ MONITOREO CATÁLOGOS
A1: 🗂️ MONITOREO DE CATÁLOGOS — RESULTADO POR CAMPAÑA | P1: #VALUE!
B2: I | D2: ingresa por cada catálogo: tu factura del mes, total de ventas, campaña. El sistema calcula ganancia real, comisión y reinversión.
C3: % COMISIÓN (editable en INICIO): | E3: ='🏠 INICIO'!D23 -> 0 | F3: ← Cámbialo en hoja INICIO
B4: 🔵 Ingresa tú | E4: ⚫ Calculado auto | H4: 🟡 % comisión | K4: 🟢 Ganancia
B6: 📌 YANBAL | K6: 📌 ESIKA
B7: CAMPAÑA N° | C7: MES | D7: 💰 MI FACTURA (lo que debo pagar) | E7: 📦 MIS VENTAS TOTALES (S/) | F7: 💵 GANANCIA BRUTA (S/) | G7: 🏆 COMISIÓN SEGÚN % | H7: ♻️ PARA REINVERTIR | I7: ✅ GANANCIA NETA REAL | K7: CAMPAÑA N° | L7: MES | M7: 💰 MI FACTURA (lo que debo pagar) | N7: 📦 MIS VENTAS TOTALES (S/) | O7: 💵 GANANCIA BRUTA (S/) | P7: 🏆 COMISIÓN SEGÚN % | Q7: ♻️ PARA REINVERTIR | R7: ✅ GANANCIA NETA REAL
B8: 1 | C8: ENERO | D8: 420 | E8: 650 | F8: =IFERROR(IF(E8="","",E8-D8),"") -> 230 | G8: =IFERROR(IF(E8="","",E8*$E$3),"") -> 0 | H8: =IFERROR(IF(D8="","",D8*0.5),"") -> 210 | I8: =IFERROR(IF(F8="","",F8-G8),"") -> 230 | K8: 1 | L8: ENERO | M8: 280 | N8: 435 | O8: =IFERROR(IF(N8="","",N8-M8),"") -> 155 | P8: =IFERROR(IF(N8="","",N8*$E$3),"") -> 0 | Q8: =IFERROR(IF(M8="","",M8*0.5),"") -> 140 | R8: =IFERROR(IF(O8="","",O8-P8),"") -> 155
B9: 2 | C9: FEBRERO | D9: 380 | E9: 590 | F9: =IFERROR(IF(E9="","",E9-D9),"") -> 210 | G9: =IFERROR(IF(E9="","",E9*$E$3),"") -> 0 | H9: =IFERROR(IF(D9="","",D9*0.5),"") -> 190 | I9: =IFERROR(IF(F9="","",F9-G9),"") -> 210 | K9: 2 | L9: FEBRERO | M9: 310 | N9: 480 | O9: =IFERROR(IF(N9="","",N9-M9),"") -> 170 | P9: =IFERROR(IF(N9="","",N9*$E$3),"") -> 0 | Q9: =IFERROR(IF(M9="","",M9*0.5),"") -> 155 | R9: =IFERROR(IF(O9="","",O9-P9),"") -> 170
B10: 3 | C10: MARZO | D10: 510 | E10: 790 | F10: =IFERROR(IF(E10="","",E10-D10),"") -> 280 | G10: =IFERROR(IF(E10="","",E10*$E$3),"") -> 0 | H10: =IFERROR(IF(D10="","",D10*0.5),"") -> 255 | I10: =IFERROR(IF(F10="","",F10-G10),"") -> 280 | K10: 3 | L10: MARZO | M10: 265 | N10: 410 | O10: =IFERROR(IF(N10="","",N10-M10),"") -> 145 | P10: =IFERROR(IF(N10="","",N10*$E$3),"") -> 0 | Q10: =IFERROR(IF(M10="","",M10*0.5),"") -> 132.5 | R10: =IFERROR(IF(O10="","",O10-P10),"") -> 145
B11: 4 | C11: ABRIL | D11: 460 | E11: 720 | F11: =IFERROR(IF(E11="","",E11-D11),"") -> 260 | G11: =IFERROR(IF(E11="","",E11*$E$3),"") -> 0 | H11: =IFERROR(IF(D11="","",D11*0.5),"") -> 230 | I11: =IFERROR(IF(F11="","",F11-G11),"") -> 260 | K11: 4 | L11: ABRIL | M11: 330 | N11: 510 | O11: =IFERROR(IF(N11="","",N11-M11),"") -> 180 | P11: =IFERROR(IF(N11="","",N11*$E$3),"") -> 0 | Q11: =IFERROR(IF(M11="","",M11*0.5),"") -> 165 | R11: =IFERROR(IF(O11="","",O11-P11),"") -> 180
B12: 5 | C12: MAYO | D12: 395 | E12: 615 | F12: =IFERROR(IF(E12="","",E12-D12),"") -> 220 | G12: =IFERROR(IF(E12="","",E12*$E$3),"") -> 0 | H12: =IFERROR(IF(D12="","",D12*0.5),"") -> 197.5 | I12: =IFERROR(IF(F12="","",F12-G12),"") -> 220 | K12: 5 | L12: MAYO | M12: 295 | N12: 460 | O12: =IFERROR(IF(N12="","",N12-M12),"") -> 165 | P12: =IFERROR(IF(N12="","",N12*$E$3),"") -> 0 | Q12: =IFERROR(IF(M12="","",M12*0.5),"") -> 147.5 | R12: =IFERROR(IF(O12="","",O12-P12),"") -> 165
B13: 6 | C13: JUNIO | D13: 480 | E13: 745 | F13: =IFERROR(IF(E13="","",E13-D13),"") -> 265 | G13: =IFERROR(IF(E13="","",E13*$E$3),"") -> 0 | H13: =IFERROR(IF(D13="","",D13*0.5),"") -> 240 | I13: =IFERROR(IF(F13="","",F13-G13),"") -> 265 | K13: 6 | L13: JUNIO | M13: 350 | N13: 540 | O13: =IFERROR(IF(N13="","",N13-M13),"") -> 190 | P13: =IFERROR(IF(N13="","",N13*$E$3),"") -> 0 | Q13: =IFERROR(IF(M13="","",M13*0.5),"") -> 175 | R13: =IFERROR(IF(O13="","",O13-P13),"") -> 190
B14: 7 | F14: =IFERROR(IF(E14="","",E14-D14),"") | G14: =IFERROR(IF(E14="","",E14*$E$3),"") | H14: =IFERROR(IF(D14="","",D14*0.5),"") | I14: =IFERROR(IF(F14="","",F14-G14),"") | K14: 7 | O14: =IFERROR(IF(N14="","",N14-M14),"") | P14: =IFERROR(IF(N14="","",N14*$E$3),"") | Q14: =IFERROR(IF(M14="","",M14*0.5),"") | R14: =IFERROR(IF(O14="","",O14-P14),"")
B15: 1 | F15: =IFERROR(IF(E15="","",E15-D15),"") | G15: =IFERROR(IF(E15="","",E15*$E$3),"") | H15: =IFERROR(IF(D15="","",D15*0.5),"") | I15: =IFERROR(IF(F15="","",F15-G15),"") | K15: 8 | O15: =IFERROR(IF(N15="","",N15-M15),"") | P15: =IFERROR(IF(N15="","",N15*$E$3),"") | Q15: =IFERROR(IF(M15="","",M15*0.5),"") | R15: =IFERROR(IF(O15="","",O15-P15),"")
B16: 2 | F16: =IFERROR(IF(E16="","",E16-D16),"") | G16: =IFERROR(IF(E16="","",E16*$E$3),"") | H16: =IFERROR(IF(D16="","",D16*0.5),"") | I16: =IFERROR(IF(F16="","",F16-G16),"") | K16: 9 | O16: =IFERROR(IF(N16="","",N16-M16),"") | P16: =IFERROR(IF(N16="","",N16*$E$3),"") | Q16: =IFERROR(IF(M16="","",M16*0.5),"") | R16: =IFERROR(IF(O16="","",O16-P16),"")
B17: 10 | F17: =IFERROR(IF(E17="","",E17-D17),"") | G17: =IFERROR(IF(E17="","",E17*$E$3),"") | H17: =IFERROR(IF(D17="","",D17*0.5),"") | I17: =IFERROR(IF(F17="","",F17-G17),"") | K17: 10 | O17: =IFERROR(IF(N17="","",N17-M17),"") | P17: =IFERROR(IF(N17="","",N17*$E$3),"") | Q17: =IFERROR(IF(M17="","",M17*0.5),"") | R17: =IFERROR(IF(O17="","",O17-P17),"")
B18: 11 | F18: =IFERROR(IF(E18="","",E18-D18),"") | G18: =IFERROR(IF(E18="","",E18*$E$3),"") | H18: =IFERROR(IF(D18="","",D18*0.5),"") | I18: =IFERROR(IF(F18="","",F18-G18),"") | K18: 11 | O18: =IFERROR(IF(N18="","",N18-M18),"") | P18: =IFERROR(IF(N18="","",N18*$E$3),"") | Q18: =IFERROR(IF(M18="","",M18*0.5),"") | R18: =IFERROR(IF(O18="","",O18-P18),"")
B19: 12 | F19: =IFERROR(IF(E19="","",E19-D19),"") | G19: =IFERROR(IF(E19="","",E19*$E$3),"") | H19: =IFERROR(IF(D19="","",D19*0.5),"") | I19: =IFERROR(IF(F19="","",F19-G19),"") | K19: 12 | O19: =IFERROR(IF(N19="","",N19-M19),"") | P19: =IFERROR(IF(N19="","",N19*$E$3),"") | Q19: =IFERROR(IF(M19="","",M19*0.5),"") | R19: =IFERROR(IF(O19="","",O19-P19),"")
B20: 13 | F20: =IFERROR(IF(E20="","",E20-D20),"") | G20: =IFERROR(IF(E20="","",E20*$E$3),"") | H20: =IFERROR(IF(D20="","",D20*0.5),"") | I20: =IFERROR(IF(F20="","",F20-G20),"") | K20: 13 | O20: =IFERROR(IF(N20="","",N20-M20),"") | P20: =IFERROR(IF(N20="","",N20*$E$3),"") | Q20: =IFERROR(IF(M20="","",M20*0.5),"") | R20: =IFERROR(IF(O20="","",O20-P20),"")
B21: TOTAL | D21: =IFERROR(SUM(D8:D20),0) -> 2645 | E21: =IFERROR(SUM(E8:E20),0) -> 4110 | F21: =IFERROR(SUM(F8:F20),0) -> 1465 | G21: =IFERROR(SUM(G8:G20),0) -> 0 | H21: =IFERROR(SUM(H8:H20),0) -> 1322.5 | I21: =IFERROR(SUM(I8:I20),0) -> 1465 | K21: TOTAL | M21: =IFERROR(SUM(M8:M20),0) -> 1830 | N21: =IFERROR(SUM(N8:N20),0) -> 2835 | O21: =IFERROR(SUM(O8:O20),0) -> 1005 | P21: =IFERROR(SUM(P8:P20),0) -> 0 | Q21: =IFERROR(SUM(Q8:Q20),0) -> 915 | R21: =IFERROR(SUM(R8:R20),0) -> 1005
B22: 💡 Ganancia bruta = Ventas − Factura | Comisión = Ventas × % | Reinversión = 50% de Factura | Ganancia neta = Bruta − Comisión | K22: 💡 Ganancia bruta = Ventas − Factura | Comisión = Ventas × % | Reinversión = 50% de Factura | Ganancia neta = Bruta − Comisión
B24: 📌 CYZONE | K24: 📌 LBEL
B25: CAMPAÑA N° | C25: MES | D25: 💰 MI FACTURA (lo que debo pagar) | E25: 📦 MIS VENTAS TOTALES (S/) | F25: 💵 GANANCIA BRUTA (S/) | G25: 🏆 COMISIÓN SEGÚN % | H25: ♻️ PARA REINVERTIR | I25: ✅ GANANCIA NETA REAL | K25: CAMPAÑA N° | L25: MES | M25: 💰 MI FACTURA (lo que debo pagar) | N25: 📦 MIS VENTAS TOTALES (S/) | O25: 💵 GANANCIA BRUTA (S/) | P25: 🏆 COMISIÓN SEGÚN % | Q25: ♻️ PARA REINVERTIR | R25: ✅ GANANCIA NETA REAL
B26: 1 | C26: ENERO | D26: 150 | E26: 235 | F26: =IFERROR(IF(E26="","",E26-D26),"") -> 85 | G26: =IFERROR(IF(E26="","",E26*$E$3),"") -> 0 | H26: =IFERROR(IF(D26="","",D26*0.5),"") -> 75 | I26: =IFERROR(IF(F26="","",F26-G26),"") -> 85 | K26: 1 | L26: ENERO | M26: 120 | N26: 188 | O26: =IFERROR(IF(N26="","",N26-M26),"") -> 68 | P26: =IFERROR(IF(N26="","",N26*$E$3),"") -> 0 | Q26: =IFERROR(IF(M26="","",M26*0.5),"") -> 60 | R26: =IFERROR(IF(O26="","",O26-P26),"") -> 68
B27: 2 | C27: FEBRERO | D27: 180 | E27: 280 | F27: =IFERROR(IF(E27="","",E27-D27),"") -> 100 | G27: =IFERROR(IF(E27="","",E27*$E$3),"") -> 0 | H27: =IFERROR(IF(D27="","",D27*0.5),"") -> 90 | I27: =IFERROR(IF(F27="","",F27-G27),"") -> 100 | K27: 2 | L27: FEBRERO | M27: 145 | N27: 227 | O27: =IFERROR(IF(N27="","",N27-M27),"") -> 82 | P27: =IFERROR(IF(N27="","",N27*$E$3),"") -> 0 | Q27: =IFERROR(IF(M27="","",M27*0.5),"") -> 72.5 | R27: =IFERROR(IF(O27="","",O27-P27),"") -> 82
B28: 3 | C28: MARZO | D28: 165 | E28: 258 | F28: =IFERROR(IF(E28="","",E28-D28),"") -> 93 | G28: =IFERROR(IF(E28="","",E28*$E$3),"") -> 0 | H28: =IFERROR(IF(D28="","",D28*0.5),"") -> 82.5 | I28: =IFERROR(IF(F28="","",F28-G28),"") -> 93 | K28: 3 | L28: MARZO | M28: 130 | N28: 204 | O28: =IFERROR(IF(N28="","",N28-M28),"") -> 74 | P28: =IFERROR(IF(N28="","",N28*$E$3),"") -> 0 | Q28: =IFERROR(IF(M28="","",M28*0.5),"") -> 65 | R28: =IFERROR(IF(O28="","",O28-P28),"") -> 74
B29: 4 | C29: ABRIL | D29: 200 | E29: 312 | F29: =IFERROR(IF(E29="","",E29-D29),"") -> 112 | G29: =IFERROR(IF(E29="","",E29*$E$3),"") -> 0 | H29: =IFERROR(IF(D29="","",D29*0.5),"") -> 100 | I29: =IFERROR(IF(F29="","",F29-G29),"") -> 112 | K29: 4 | L29: ABRIL | M29: 160 | N29: 251 | O29: =IFERROR(IF(N29="","",N29-M29),"") -> 91 | P29: =IFERROR(IF(N29="","",N29*$E$3),"") -> 0 | Q29: =IFERROR(IF(M29="","",M29*0.5),"") -> 80 | R29: =IFERROR(IF(O29="","",O29-P29),"") -> 91
B30: 1 | C30: MAYO | D30: 175 | E30: 274 | F30: =IFERROR(IF(E30="","",E30-D30),"") -> 99 | G30: =IFERROR(IF(E30="","",E30*$E$3),"") -> 0 | H30: =IFERROR(IF(D30="","",D30*0.5),"") -> 87.5 | I30: =IFERROR(IF(F30="","",F30-G30),"") -> 99 | K30: 5 | L30: MAYO | M30: 135 | N30: 212 | O30: =IFERROR(IF(N30="","",N30-M30),"") -> 77 | P30: =IFERROR(IF(N30="","",N30*$E$3),"") -> 0 | Q30: =IFERROR(IF(M30="","",M30*0.5),"") -> 67.5 | R30: =IFERROR(IF(O30="","",O30-P30),"") -> 77
B31: 6 | C31: JUNIO | D31: 210 | E31: 328 | F31: =IFERROR(IF(E31="","",E31-D31),"") -> 118 | G31: =IFERROR(IF(E31="","",E31*$E$3),"") -> 0 | H31: =IFERROR(IF(D31="","",D31*0.5),"") -> 105 | I31: =IFERROR(IF(F31="","",F31-G31),"") -> 118 | K31: 6 | L31: JUNIO | M31: 155 | N31: 243 | O31: =IFERROR(IF(N31="","",N31-M31),"") -> 88 | P31: =IFERROR(IF(N31="","",N31*$E$3),"") -> 0 | Q31: =IFERROR(IF(M31="","",M31*0.5),"") -> 77.5 | R31: =IFERROR(IF(O31="","",O31-P31),"") -> 88
B32: 7 | F32: =IFERROR(IF(E32="","",E32-D32),"") | G32: =IFERROR(IF(E32="","",E32*$E$3),"") | H32: =IFERROR(IF(D32="","",D32*0.5),"") | I32: =IFERROR(IF(F32="","",F32-G32),"") | K32: 7 | O32: =IFERROR(IF(N32="","",N32-M32),"") | P32: =IFERROR(IF(N32="","",N32*$E$3),"") | Q32: =IFERROR(IF(M32="","",M32*0.5),"") | R32: =IFERROR(IF(O32="","",O32-P32),"")
B33: 8 | F33: =IFERROR(IF(E33="","",E33-D33),"") | G33: =IFERROR(IF(E33="","",E33*$E$3),"") | H33: =IFERROR(IF(D33="","",D33*0.5),"") | I33: =IFERROR(IF(F33="","",F33-G33),"") | K33: 8 | O33: =IFERROR(IF(N33="","",N33-M33),"") | P33: =IFERROR(IF(N33="","",N33*$E$3),"") | Q33: =IFERROR(IF(M33="","",M33*0.5),"") | R33: =IFERROR(IF(O33="","",O33-P33),"")
B34: 9 | F34: =IFERROR(IF(E34="","",E34-D34),"") | G34: =IFERROR(IF(E34="","",E34*$E$3),"") | H34: =IFERROR(IF(D34="","",D34*0.5),"") | I34: =IFERROR(IF(F34="","",F34-G34),"") | K34: 9 | O34: =IFERROR(IF(N34="","",N34-M34),"") | P34: =IFERROR(IF(N34="","",N34*$E$3),"") | Q34: =IFERROR(IF(M34="","",M34*0.5),"") | R34: =IFERROR(IF(O34="","",O34-P34),"")
B35: 10 | F35: =IFERROR(IF(E35="","",E35-D35),"") | G35: =IFERROR(IF(E35="","",E35*$E$3),"") | H35: =IFERROR(IF(D35="","",D35*0.5),"") | I35: =IFERROR(IF(F35="","",F35-G35),"") | K35: 10 | O35: =IFERROR(IF(N35="","",N35-M35),"") | P35: =IFERROR(IF(N35="","",N35*$E$3),"") | Q35: =IFERROR(IF(M35="","",M35*0.5),"") | R35: =IFERROR(IF(O35="","",O35-P35),"")
B36: 11 | F36: =IFERROR(IF(E36="","",E36-D36),"") | G36: =IFERROR(IF(E36="","",E36*$E$3),"") | H36: =IFERROR(IF(D36="","",D36*0.5),"") | I36: =IFERROR(IF(F36="","",F36-G36),"") | K36: 11 | O36: =IFERROR(IF(N36="","",N36-M36),"") | P36: =IFERROR(IF(N36="","",N36*$E$3),"") | Q36: =IFERROR(IF(M36="","",M36*0.5),"") | R36: =IFERROR(IF(O36="","",O36-P36),"")
B37: 12 | F37: =IFERROR(IF(E37="","",E37-D37),"") | G37: =IFERROR(IF(E37="","",E37*$E$3),"") | H37: =IFERROR(IF(D37="","",D37*0.5),"") | I37: =IFERROR(IF(F37="","",F37-G37),"") | K37: 12 | O37: =IFERROR(IF(N37="","",N37-M37),"") | P37: =IFERROR(IF(N37="","",N37*$E$3),"") | Q37: =IFERROR(IF(M37="","",M37*0.5),"") | R37: =IFERROR(IF(O37="","",O37-P37),"")
B38: 13 | F38: =IFERROR(IF(E38="","",E38-D38),"") | G38: =IFERROR(IF(E38="","",E38*$E$3),"") | H38: =IFERROR(IF(D38="","",D38*0.5),"") | I38: =IFERROR(IF(F38="","",F38-G38),"") | K38: 13 | O38: =IFERROR(IF(N38="","",N38-M38),"") | P38: =IFERROR(IF(N38="","",N38*$E$3),"") | Q38: =IFERROR(IF(M38="","",M38*0.5),"") | R38: =IFERROR(IF(O38="","",O38-P38),"")
B39: TOTAL | D39: =IFERROR(SUM(D26:D38),0) -> 1080 | E39: =IFERROR(SUM(E26:E38),0) -> 1687 | F39: =IFERROR(SUM(F26:F38),0) -> 607 | G39: =IFERROR(SUM(G26:G38),0) -> 0 | H39: =IFERROR(SUM(H26:H38),0) -> 540 | I39: =IFERROR(SUM(I26:I38),0) -> 607 | K39: TOTAL | M39: =IFERROR(SUM(M26:M38),0) -> 845 | N39: =IFERROR(SUM(N26:N38),0) -> 1325 | O39: =IFERROR(SUM(O26:O38),0) -> 480 | P39: =IFERROR(SUM(P26:P38),0) -> 0 | Q39: =IFERROR(SUM(Q26:Q38),0) -> 422.5 | R39: =IFERROR(SUM(R26:R38),0) -> 480
B40: 💡 Ganancia bruta = Ventas − Factura | Comisión = Ventas × % | Reinversión = 50% de Factura | Ganancia neta = Bruta − Comisión | K40: 💡 Ganancia bruta = Ventas − Factura | Comisión = Ventas × % | Reinversión = 50% de Factura | Ganancia neta = Bruta − Comisión
B42: 📌 NATURA | K42: 📌 AVON
B43: CAMPAÑA N° | C43: MES | D43: 💰 MI FACTURA (lo que debo pagar) | E43: 📦 MIS VENTAS TOTALES (S/) | F43: 💵 GANANCIA BRUTA (S/) | G43: 🏆 COMISIÓN SEGÚN % | H43: ♻️ PARA REINVERTIR | I43: ✅ GANANCIA NETA REAL | K43: CAMPAÑA N° | L43: MES | M43: 💰 MI FACTURA (lo que debo pagar) | N43: 📦 MIS VENTAS TOTALES (S/) | O43: 💵 GANANCIA BRUTA (S/) | P43: 🏆 COMISIÓN SEGÚN % | Q43: ♻️ PARA REINVERTIR | R43: ✅ GANANCIA NETA REAL
...

Sheet SEG - ENERO
A1: #VALUE! | B1: ✅ SEGUIMIENTO DE VENTAS — ENERO
B2: Registra tus ventas del mes. Usa los desplegables para catálogo, método de pago y estado.
B3: 🔍 Filtros (▼): Campaña · Catálogo · Método de pago · Estado | 🟢 PAGADO 🔴 FALTA CANCELAR 🟡 ADELANTO
A4: CAMPAÑA N° | B4: # | C4: CLIENTE | D4: PRODUCTO | E4: CATÁLOGO | F4: PRECIO (S/) | G4: MÉTODO PAGO | H4: ESTADO PAGO | I4: ADELANTO S/ | J4: NOTAS | K4: COMISIÓN (S/)
A5: 2 | B5: 1 | C5: PAOLA | D5: OHM NOW | E5: YANBAL | F5: 90 | G5: EFECTIVO | H5: PAGADO | K5: =IF(F5="","",F5*'🏠 INICIO'!C8) -> 9
A6: 5 | B6: 2 | K6: =IF(F6="","",F6*'🏠 INICIO'!C8)
B7: 3 | K7: =IF(F7="","",F7*'🏠 INICIO'!C8)
B8: 4 | K8: =IF(F8="","",F8*'🏠 INICIO'!C8)
B9: 5 | K9: =IF(F9="","",F9*'🏠 INICIO'!C8)
B10: 6 | K10: =IF(F10="","",F10*'🏠 INICIO'!C8)
B11: 7 | K11: =IF(F11="","",F11*'🏠 INICIO'!C8)
B12: 8 | K12: =IF(F12="","",F12*'🏠 INICIO'!C8)
B13: 9 | K13: =IF(F13="","",F13*'🏠 INICIO'!C8)
B14: 10 | K14: =IF(F14="","",F14*'🏠 INICIO'!C8)
B15: 11 | K15: =IF(F15="","",F15*'🏠 INICIO'!C8)
B16: 12 | K16: =IF(F16="","",F16*'🏠 INICIO'!C8)
B17: 13 | K17: =IF(F17="","",F17*'🏠 INICIO'!C8)
B18: 14 | K18: =IF(F18="","",F18*'🏠 INICIO'!C8)
B19: 15 | K19: =IF(F19="","",F19*'🏠 INICIO'!C8)
B20: 16 | K20: =IF(F20="","",F20*'🏠 INICIO'!C8)
B21: 17 | K21: =IF(F21="","",F21*'🏠 INICIO'!C8)
B22: 18 | K22: =IF(F22="","",F22*'🏠 INICIO'!C8)
B23: 19 | K23: =IF(F23="","",F23*'🏠 INICIO'!C8)
B24: 20 | K24: =IF(F24="","",F24*'🏠 INICIO'!C8)
B25: 21 | K25: =IF(F25="","",F25*'🏠 INICIO'!C8)
B26: 22 | K26: =IF(F26="","",F26*'🏠 INICIO'!C8)
B27: 23 | K27: =IF(F27="","",F27*'🏠 INICIO'!C8)
B28: 24 | K28: =IF(F28="","",F28*'🏠 INICIO'!C8)
B29: 25 | K29: =IF(F29="","",F29*'🏠 INICIO'!C8)
B30: 26 | K30: =IF(F30="","",F30*'🏠 INICIO'!C8)
B31: 27 | K31: =IF(F31="","",F31*'🏠 INICIO'!C8)
B32: 28 | K32: =IF(F32="","",F32*'🏠 INICIO'!C8)
B33: 29 | K33: =IF(F33="","",F33*'🏠 INICIO'!C8)
B34: 30 | K34: =IF(F34="","",F34*'🏠 INICIO'!C8)
B35: 31 | K35: =IF(F35="","",F35*'🏠 INICIO'!C8)
B36: 32 | K36: =IF(F36="","",F36*'🏠 INICIO'!C8)
B37: 33 | K37: =IF(F37="","",F37*'🏠 INICIO'!C8)
B38: 34 | K38: =IF(F38="","",F38*'🏠 INICIO'!C8)
B39: 35 | K39: =IF(F39="","",F39*'🏠 INICIO'!C8)
B40: 36 | K40: =IF(F40="","",F40*'🏠 INICIO'!C8)
...

Sheet SEG - FEBRERO
A1: #VALUE! | B1: ✅ SEGUIMIENTO DE VENTAS — FEBRERO
B2: Registra tus ventas del mes. Usa los desplegables para catálogo, método de pago y estado.
B3: 🔍 Filtros (▼): Campaña · Catálogo · Método de pago · Estado | 🟢 PAGADO 🔴 FALTA CANCELAR 🟡 ADELANTO
A4: CAMPAÑA N° | B4: # | C4: CLIENTE | D4: PRODUCTO | E4: CATÁLOGO | F4: PRECIO (S/) | G4: MÉTODO PAGO | H4: ESTADO PAGO | I4: ADELANTO S/ | J4: NOTAS | K4: COMISIÓN (S/)
A5: 2 | B5: 1 | C5: PAOLA | D5: OHM NOW | E5: YANBAL | F5: 90 | G5: EFECTIVO | H5: PAGADO | K5: =IF(F5="","",F5*'🏠 INICIO'!C8) -> 9
A6: 5 | B6: 2 | K6: =IF(F6="","",F6*'🏠 INICIO'!C8)
B7: 3 | K7: =IF(F7="","",F7*'🏠 INICIO'!C8)
B8: 4 | K8: =IF(F8="","",F8*'🏠 INICIO'!C8)
B9: 5 | K9: =IF(F9="","",F9*'🏠 INICIO'!C8)
B10: 6 | K10: =IF(F10="","",F10*'🏠 INICIO'!C8)
B11: 7 | K11: =IF(F11="","",F11*'🏠 INICIO'!C8)
B12: 8 | K12: =IF(F12="","",F12*'🏠 INICIO'!C8)
B13: 9 | K13: =IF(F13="","",F13*'🏠 INICIO'!C8)
B14: 10 | K14: =IF(F14="","",F14*'🏠 INICIO'!C8)
B15: 11 | K15: =IF(F15="","",F15*'🏠 INICIO'!C8)
B16: 12 | K16: =IF(F16="","",F16*'🏠 INICIO'!C8)
B17: 13 | K17: =IF(F17="","",F17*'🏠 INICIO'!C8)
B18: 14 | K18: =IF(F18="","",F18*'🏠 INICIO'!C8)
B19: 15 | K19: =IF(F19="","",F19*'🏠 INICIO'!C8)
B20: 16 | K20: =IF(F20="","",F20*'🏠 INICIO'!C8)
B21: 17 | K21: =IF(F21="","",F21*'🏠 INICIO'!C8)
B22: 18 | K22: =IF(F22="","",F22*'🏠 INICIO'!C8)
B23: 19 | K23: =IF(F23="","",F23*'🏠 INICIO'!C8)
B24: 20 | K24: =IF(F24="","",F24*'🏠 INICIO'!C8)
B25: 21 | K25: =IF(F25="","",F25*'🏠 INICIO'!C8)
B26: 22 | K26: =IF(F26="","",F26*'🏠 INICIO'!C8)
B27: 23 | K27: =IF(F27="","",F27*'🏠 INICIO'!C8)
B28: 24 | K28: =IF(F28="","",F28*'🏠 INICIO'!C8)
B29: 25 | K29: =IF(F29="","",F29*'🏠 INICIO'!C8)
B30: 26 | K30: =IF(F30="","",F30*'🏠 INICIO'!C8)
B31: 27 | K31: =IF(F31="","",F31*'🏠 INICIO'!C8)
B32: 28 | K32: =IF(F32="","",F32*'🏠 INICIO'!C8)
B33: 29 | K33: =IF(F33="","",F33*'🏠 INICIO'!C8)
B34: 30 | K34: =IF(F34="","",F34*'🏠 INICIO'!C8)
B35: 31 | K35: =IF(F35="","",F35*'🏠 INICIO'!C8)
B36: 32 | K36: =IF(F36="","",F36*'🏠 INICIO'!C8)
B37: 33 | K37: =IF(F37="","",F37*'🏠 INICIO'!C8)
B38: 34 | K38: =IF(F38="","",F38*'🏠 INICIO'!C8)
B39: 35 | K39: =IF(F39="","",F39*'🏠 INICIO'!C8)
B40: 36 | K40: =IF(F40="","",F40*'🏠 INICIO'!C8)
...

Sheet SEG - MARZO
A1: #VALUE! | B1: ✅ SEGUIMIENTO DE VENTAS — MARZO
B2: Registra tus ventas del mes. Usa los desplegables para catálogo, método de pago y estado.
B3: 🔍 Filtros (▼): Campaña · Catálogo · Método de pago · Estado | 🟢 PAGADO 🔴 FALTA CANCELAR 🟡 ADELANTO
A4: CAMPAÑA N° | B4: # | C4: CLIENTE | D4: PRODUCTO | E4: CATÁLOGO | F4: PRECIO (S/) | G4: MÉTODO PAGO | H4: ESTADO PAGO | I4: ADELANTO S/ | J4: NOTAS | K4: COMISIÓN (S/)
A5: 2 | B5: 1 | C5: PAOLA | D5: OHM NOW | E5: YANBAL | F5: 90 | G5: EFECTIVO | H5: PAGADO | K5: =IF(F5="","",F5*'🏠 INICIO'!C8) -> 9
A6: 5 | B6: 2 | K6: =IF(F6="","",F6*'🏠 INICIO'!C8)
B7: 3 | K7: =IF(F7="","",F7*'🏠 INICIO'!C8)
B8: 4 | K8: =IF(F8="","",F8*'🏠 INICIO'!C8)
B9: 5 | K9: =IF(F9="","",F9*'🏠 INICIO'!C8)
B10: 6 | K10: =IF(F10="","",F10*'🏠 INICIO'!C8)
B11: 7 | K11: =IF(F11="","",F11*'🏠 INICIO'!C8)
B12: 8 | K12: =IF(F12="","",F12*'🏠 INICIO'!C8)
B13: 9 | K13: =IF(F13="","",F13*'🏠 INICIO'!C8)
B14: 10 | K14: =IF(F14="","",F14*'🏠 INICIO'!C8)
B15: 11 | K15: =IF(F15="","",F15*'🏠 INICIO'!C8)
B16: 12 | K16: =IF(F16="","",F16*'🏠 INICIO'!C8)
B17: 13 | K17: =IF(F17="","",F17*'🏠 INICIO'!C8)
B18: 14 | K18: =IF(F18="","",F18*'🏠 INICIO'!C8)
B19: 15 | K19: =IF(F19="","",F19*'🏠 INICIO'!C8)
B20: 16 | K20: =IF(F20="","",F20*'🏠 INICIO'!C8)
B21: 17 | K21: =IF(F21="","",F21*'🏠 INICIO'!C8)
B22: 18 | K22: =IF(F22="","",F22*'🏠 INICIO'!C8)
B23: 19 | K23: =IF(F23="","",F23*'🏠 INICIO'!C8)
B24: 20 | K24: =IF(F24="","",F24*'🏠 INICIO'!C8)
B25: 21 | K25: =IF(F25="","",F25*'🏠 INICIO'!C8)
B26: 22 | K26: =IF(F26="","",F26*'🏠 INICIO'!C8)
B27: 23 | K27: =IF(F27="","",F27*'🏠 INICIO'!C8)
B28: 24 | K28: =IF(F28="","",F28*'🏠 INICIO'!C8)
B29: 25 | K29: =IF(F29="","",F29*'🏠 INICIO'!C8)
B30: 26 | K30: =IF(F30="","",F30*'🏠 INICIO'!C8)
B31: 27 | K31: =IF(F31="","",F31*'🏠 INICIO'!C8)
B32: 28 | K32: =IF(F32="","",F32*'🏠 INICIO'!C8)
B33: 29 | K33: =IF(F33="","",F33*'🏠 INICIO'!C8)
B34: 30 | K34: =IF(F34="","",F34*'🏠 INICIO'!C8)
B35: 31 | K35: =IF(F35="","",F35*'🏠 INICIO'!C8)
B36: 32 | K36: =IF(F36="","",F36*'🏠 INICIO'!C8)
B37: 33 | K37: =IF(F37="","",F37*'🏠 INICIO'!C8)
B38: 34 | K38: =IF(F38="","",F38*'🏠 INICIO'!C8)
B39: 35 | K39: =IF(F39="","",F39*'🏠 INICIO'!C8)
B40: 36 | K40: =IF(F40="","",F40*'🏠 INICIO'!C8)
...

Sheet SEG - ABRIL
A1: #VALUE! | B1: ✅ SEGUIMIENTO DE VENTAS — ABRIL
B2: Registra tus ventas del mes. Usa los desplegables para catálogo, método de pago y estado.
B3: 🔍 Filtros (▼): Campaña · Catálogo · Método de pago · Estado | 🟢 PAGADO 🔴 FALTA CANCELAR 🟡 ADELANTO
A4: CAMPAÑA N° | B4: # | C4: CLIENTE | D4: PRODUCTO | E4: CATÁLOGO | F4: PRECIO (S/) | G4: MÉTODO PAGO | H4: ESTADO PAGO | I4: ADELANTO S/ | J4: NOTAS | K4: COMISIÓN (S/)
A5: 2 | B5: 1 | C5: PAOLA | D5: OHM NOW | E5: YANBAL | F5: 90 | G5: EFECTIVO | H5: ADELANTO | I5: 50 | K5: =IF(F5="","",F5*'🏠 INICIO'!C8) -> 9
A6: 5 | B6: 2 | K6: =IF(F6="","",F6*'🏠 INICIO'!C8)
B7: 3 | K7: =IF(F7="","",F7*'🏠 INICIO'!C8)
B8: 4 | K8: =IF(F8="","",F8*'🏠 INICIO'!C8)
B9: 5 | K9: =IF(F9="","",F9*'🏠 INICIO'!C8)
B10: 6 | K10: =IF(F10="","",F10*'🏠 INICIO'!C8)
B11: 7 | K11: =IF(F11="","",F11*'🏠 INICIO'!C8)
B12: 8 | K12: =IF(F12="","",F12*'🏠 INICIO'!C8)
B13: 9 | K13: =IF(F13="","",F13*'🏠 INICIO'!C8)
B14: 10 | K14: =IF(F14="","",F14*'🏠 INICIO'!C8)
B15: 11 | K15: =IF(F15="","",F15*'🏠 INICIO'!C8)
B16: 12 | K16: =IF(F16="","",F16*'🏠 INICIO'!C8)
B17: 13 | K17: =IF(F17="","",F17*'🏠 INICIO'!C8)
B18: 14 | K18: =IF(F18="","",F18*'🏠 INICIO'!C8)
B19: 15 | K19: =IF(F19="","",F19*'🏠 INICIO'!C8)
B20: 16 | K20: =IF(F20="","",F20*'🏠 INICIO'!C8)
B21: 17 | K21: =IF(F21="","",F21*'🏠 INICIO'!C8)
B22: 18 | K22: =IF(F22="","",F22*'🏠 INICIO'!C8)
B23: 19 | K23: =IF(F23="","",F23*'🏠 INICIO'!C8)
B24: 20 | K24: =IF(F24="","",F24*'🏠 INICIO'!C8)
B25: 21 | K25: =IF(F25="","",F25*'🏠 INICIO'!C8)
B26: 22 | K26: =IF(F26="","",F26*'🏠 INICIO'!C8)
B27: 23 | K27: =IF(F27="","",F27*'🏠 INICIO'!C8)
B28: 24 | K28: =IF(F28="","",F28*'🏠 INICIO'!C8)
B29: 25 | K29: =IF(F29="","",F29*'🏠 INICIO'!C8)
B30: 26 | K30: =IF(F30="","",F30*'🏠 INICIO'!C8)
B31: 27 | K31: =IF(F31="","",F31*'🏠 INICIO'!C8)
B32: 28 | K32: =IF(F32="","",F32*'🏠 INICIO'!C8)
B33: 29 | K33: =IF(F33="","",F33*'🏠 INICIO'!C8)
B34: 30 | K34: =IF(F34="","",F34*'🏠 INICIO'!C8)
B35: 31 | K35: =IF(F35="","",F35*'🏠 INICIO'!C8)
B36: 32 | K36: =IF(F36="","",F36*'🏠 INICIO'!C8)
B37: 33 | K37: =IF(F37="","",F37*'🏠 INICIO'!C8)
B38: 34 | K38: =IF(F38="","",F38*'🏠 INICIO'!C8)
B39: 35 | K39: =IF(F39="","",F39*'🏠 INICIO'!C8)
B40: 36 | K40: =IF(F40="","",F40*'🏠 INICIO'!C8)
...

Sheet SEG - MAYO
A1: #VALUE! | B1: ✅ SEGUIMIENTO DE VENTAS — MAYO
B2: Registra tus ventas del mes. Usa los desplegables para catálogo, método de pago y estado.
B3: 🔍 Filtros (▼): Campaña · Catálogo · Método de pago · Estado | 🟢 PAGADO 🔴 FALTA CANCELAR 🟡 ADELANTO
A4: CAMPAÑA N° | B4: # | C4: CLIENTE | D4: PRODUCTO | E4: CATÁLOGO | F4: PRECIO (S/) | G4: MÉTODO PAGO | H4: ESTADO PAGO | I4: ADELANTO S/ | J4: NOTAS | K4: COMISIÓN (S/)
A5: 2 | B5: 1 | C5: PAOLA | D5: OHM NOW | E5: YANBAL | F5: 90 | G5: EFECTIVO | H5: PAGADO | K5: =IF(F5="","",F5*'🏠 INICIO'!C8) -> 9
A6: 5 | B6: 2 | K6: =IF(F6="","",F6*'🏠 INICIO'!C8)
B7: 3 | K7: =IF(F7="","",F7*'🏠 INICIO'!C8)
B8: 4 | K8: =IF(F8="","",F8*'🏠 INICIO'!C8)
B9: 5 | K9: =IF(F9="","",F9*'🏠 INICIO'!C8)
B10: 6 | K10: =IF(F10="","",F10*'🏠 INICIO'!C8)
B11: 7 | K11: =IF(F11="","",F11*'🏠 INICIO'!C8)
B12: 8 | K12: =IF(F12="","",F12*'🏠 INICIO'!C8)
B13: 9 | K13: =IF(F13="","",F13*'🏠 INICIO'!C8)
B14: 10 | K14: =IF(F14="","",F14*'🏠 INICIO'!C8)
B15: 11 | K15: =IF(F15="","",F15*'🏠 INICIO'!C8)
B16: 12 | K16: =IF(F16="","",F16*'🏠 INICIO'!C8)
B17: 13 | K17: =IF(F17="","",F17*'🏠 INICIO'!C8)
B18: 14 | K18: =IF(F18="","",F18*'🏠 INICIO'!C8)
B19: 15 | K19: =IF(F19="","",F19*'🏠 INICIO'!C8)
B20: 16 | K20: =IF(F20="","",F20*'🏠 INICIO'!C8)
B21: 17 | K21: =IF(F21="","",F21*'🏠 INICIO'!C8)
B22: 18 | K22: =IF(F22="","",F22*'🏠 INICIO'!C8)
B23: 19 | K23: =IF(F23="","",F23*'🏠 INICIO'!C8)
B24: 20 | K24: =IF(F24="","",F24*'🏠 INICIO'!C8)
B25: 21 | K25: =IF(F25="","",F25*'🏠 INICIO'!C8)
B26: 22 | K26: =IF(F26="","",F26*'🏠 INICIO'!C8)
B27: 23 | K27: =IF(F27="","",F27*'🏠 INICIO'!C8)
B28: 24 | K28: =IF(F28="","",F28*'🏠 INICIO'!C8)
B29: 25 | K29: =IF(F29="","",F29*'🏠 INICIO'!C8)
B30: 26 | K30: =IF(F30="","",F30*'🏠 INICIO'!C8)
B31: 27 | K31: =IF(F31="","",F31*'🏠 INICIO'!C8)
B32: 28 | K32: =IF(F32="","",F32*'🏠 INICIO'!C8)
B33: 29 | K33: =IF(F33="","",F33*'🏠 INICIO'!C8)
B34: 30 | K34: =IF(F34="","",F34*'🏠 INICIO'!C8)
B35: 31 | K35: =IF(F35="","",F35*'🏠 INICIO'!C8)
B36: 32 | K36: =IF(F36="","",F36*'🏠 INICIO'!C8)
B37: 33 | K37: =IF(F37="","",F37*'🏠 INICIO'!C8)
B38: 34 | K38: =IF(F38="","",F38*'🏠 INICIO'!C8)
B39: 35 | K39: =IF(F39="","",F39*'🏠 INICIO'!C8)
B40: 36 | K40: =IF(F40="","",F40*'🏠 INICIO'!C8)
...

Sheet SEG - JUNIO
A1: #VALUE! | B1: ✅ SEGUIMIENTO DE VENTAS — JUNIO
B2: Registra tus ventas del mes. Usa los desplegables para catálogo, método de pago y estado.
B3: 🔍 Filtros (▼): Campaña · Catálogo · Método de pago · Estado | 🟢 PAGADO 🔴 FALTA CANCELAR 🟡 ADELANTO
A4: CAMPAÑA N° | B4: # | C4: CLIENTE | D4: PRODUCTO | E4: CATÁLOGO | F4: PRECIO (S/) | G4: MÉTODO PAGO | H4: ESTADO PAGO | I4: ADELANTO S/ | J4: NOTAS | K4: COMISIÓN (S/)
A5: 2 | B5: 1 | C5: PAOLA | D5: OHM NOW | E5: YANBAL | F5: 90 | G5: EFECTIVO | H5: PAGADO | K5: =IF(F5="","",F5*'🏠 INICIO'!C8) -> 9
A6: 5 | B6: 2 | K6: =IF(F6="","",F6*'🏠 INICIO'!C8)
B7: 3 | K7: =IF(F7="","",F7*'🏠 INICIO'!C8)
B8: 4 | K8: =IF(F8="","",F8*'🏠 INICIO'!C8)
B9: 5 | K9: =IF(F9="","",F9*'🏠 INICIO'!C8)
B10: 6 | K10: =IF(F10="","",F10*'🏠 INICIO'!C8)
B11: 7 | K11: =IF(F11="","",F11*'🏠 INICIO'!C8)
B12: 8 | K12: =IF(F12="","",F12*'🏠 INICIO'!C8)
B13: 9 | K13: =IF(F13="","",F13*'🏠 INICIO'!C8)
B14: 10 | K14: =IF(F14="","",F14*'🏠 INICIO'!C8)
B15: 11 | K15: =IF(F15="","",F15*'🏠 INICIO'!C8)
B16: 12 | K16: =IF(F16="","",F16*'🏠 INICIO'!C8)
B17: 13 | K17: =IF(F17="","",F17*'🏠 INICIO'!C8)
B18: 14 | K18: =IF(F18="","",F18*'🏠 INICIO'!C8)
B19: 15 | K19: =IF(F19="","",F19*'🏠 INICIO'!C8)
B20: 16 | K20: =IF(F20="","",F20*'🏠 INICIO'!C8)
B21: 17 | K21: =IF(F21="","",F21*'🏠 INICIO'!C8)
B22: 18 | K22: =IF(F22="","",F22*'🏠 INICIO'!C8)
B23: 19 | K23: =IF(F23="","",F23*'🏠 INICIO'!C8)
B24: 20 | K24: =IF(F24="","",F24*'🏠 INICIO'!C8)
B25: 21 | K25: =IF(F25="","",F25*'🏠 INICIO'!C8)
B26: 22 | K26: =IF(F26="","",F26*'🏠 INICIO'!C8)
B27: 23 | K27: =IF(F27="","",F27*'🏠 INICIO'!C8)
B28: 24 | K28: =IF(F28="","",F28*'🏠 INICIO'!C8)
B29: 25 | K29: =IF(F29="","",F29*'🏠 INICIO'!C8)
B30: 26 | K30: =IF(F30="","",F30*'🏠 INICIO'!C8)
B31: 27 | K31: =IF(F31="","",F31*'🏠 INICIO'!C8)
B32: 28 | K32: =IF(F32="","",F32*'🏠 INICIO'!C8)
B33: 29 | K33: =IF(F33="","",F33*'🏠 INICIO'!C8)
B34: 30 | K34: =IF(F34="","",F34*'🏠 INICIO'!C8)
B35: 31 | K35: =IF(F35="","",F35*'🏠 INICIO'!C8)
B36: 32 | K36: =IF(F36="","",F36*'🏠 INICIO'!C8)
B37: 33 | K37: =IF(F37="","",F37*'🏠 INICIO'!C8)
B38: 34 | K38: =IF(F38="","",F38*'🏠 INICIO'!C8)
B39: 35 | K39: =IF(F39="","",F39*'🏠 INICIO'!C8)
B40: 36 | K40: =IF(F40="","",F40*'🏠 INICIO'!C8)
...

Sheet SEG - JULIO
A1: #VALUE! | B1: ✅ SEGUIMIENTO DE VENTAS — JULIO
B2: Registra tus ventas del mes. Usa los desplegables para catálogo, método de pago y estado.
B3: 🔍 Filtros (▼): Campaña · Catálogo · Método de pago · Estado | 🟢 PAGADO 🔴 FALTA CANCELAR 🟡 ADELANTO
A4: CAMPAÑA N° | B4: # | C4: CLIENTE | D4: PRODUCTO | E4: CATÁLOGO | F4: PRECIO (S/) | G4: MÉTODO PAGO | H4: ESTADO PAGO | I4: ADELANTO S/ | J4: NOTAS | K4: COMISIÓN (S/)
